[2024-04-08T14:58:23.164+0000] {taskinstance.py:1979} INFO - Dependencies all met for dep_context=non-requeueable deps ti=<TaskInstance: cassandra_sensor_dag.cassandra_sensor_record scheduled__2024-04-08T00:25:00+00:00 [queued]>
[2024-04-08T14:58:23.347+0000] {taskinstance.py:1979} INFO - Dependencies all met for dep_context=requeueable deps ti=<TaskInstance: cassandra_sensor_dag.cassandra_sensor_record scheduled__2024-04-08T00:25:00+00:00 [queued]>
[2024-04-08T14:58:23.420+0000] {taskinstance.py:2193} INFO - Starting attempt 1 of 2
[2024-04-08T14:58:24.017+0000] {taskinstance.py:2217} INFO - Executing <Task(CassandraRecordSensor): cassandra_sensor_record> on 2024-04-08 00:25:00+00:00
[2024-04-08T14:58:24.127+0000] {standard_task_runner.py:60} INFO - Started process 1129 to run task
[2024-04-08T14:58:24.186+0000] {standard_task_runner.py:87} INFO - Running: ['***', 'tasks', 'run', 'cassandra_sensor_dag', 'cassandra_sensor_record', 'scheduled__2024-04-08T00:25:00+00:00', '--job-id', '108', '--raw', '--subdir', 'DAGS_FOLDER/test.py', '--cfg-path', '/tmp/tmp3rubi8u1']
[2024-04-08T14:58:24.234+0000] {standard_task_runner.py:88} INFO - Job 108: Subtask cassandra_sensor_record
[2024-04-08T14:58:25.101+0000] {task_command.py:423} INFO - Running <TaskInstance: cassandra_sensor_dag.cassandra_sensor_record scheduled__2024-04-08T00:25:00+00:00 [running]> on host c2d2cc8ff432
[2024-04-08T14:58:26.832+0000] {taskinstance.py:2513} INFO - Exporting env vars: AIRFLOW_CTX_DAG_OWNER='***' AIRFLOW_CTX_DAG_ID='cassandra_sensor_dag' AIRFLOW_CTX_TASK_ID='cassandra_sensor_record' AIRFLOW_CTX_EXECUTION_DATE='2024-04-08T00:25:00+00:00' AIRFLOW_CTX_TRY_NUMBER='1' AIRFLOW_CTX_DAG_RUN_ID='scheduled__2024-04-08T00:25:00+00:00'
[2024-04-08T14:58:26.859+0000] {record.py:71} INFO - Sensor check existence of record: ['user_id', 'age', 'email', 'name']
[2024-04-08T14:58:26.996+0000] {base.py:83} INFO - Using connection ID 'cassandra_conn' for task execution.
[2024-04-08T14:58:27.048+0000] {warnings.py:109} WARNING - /home/***/.local/lib/python3.8/site-packages/***/providers/apache/cassandra/hooks/cassandra.py:120: DeprecationWarning: Legacy execution parameters will be removed in 4.0. Consider using execution profiles.
  self.cluster = Cluster(**conn_config)

[2024-04-08T14:58:27.492+0000] {cassandra.py:128} WARNING - Downgrading core protocol version from 66 to 65 for 172.21.0.4:9042. To avoid this, it is best practice to explicitly set Cluster(protocol_version) to the version supported by your cluster. http://datastax.github.io/python-driver/api/cassandra/cluster.html#cassandra.cluster.Cluster.protocol_version
[2024-04-08T14:58:27.510+0000] {cassandra.py:128} WARNING - Downgrading core protocol version from 65 to 5 for 172.21.0.4:9042. To avoid this, it is best practice to explicitly set Cluster(protocol_version) to the version supported by your cluster. http://datastax.github.io/python-driver/api/cassandra/cluster.html#cassandra.cluster.Cluster.protocol_version
[2024-04-08T14:59:29.639+0000] {record.py:71} INFO - Sensor check existence of record: ['user_id', 'age', 'email', 'name']
[2024-04-08T14:59:29.705+0000] {base.py:83} INFO - Using connection ID 'cassandra_conn' for task execution.
[2024-04-08T14:59:29.863+0000] {cassandra.py:128} WARNING - Downgrading core protocol version from 66 to 65 for 172.21.0.4:9042. To avoid this, it is best practice to explicitly set Cluster(protocol_version) to the version supported by your cluster. http://datastax.github.io/python-driver/api/cassandra/cluster.html#cassandra.cluster.Cluster.protocol_version
[2024-04-08T14:59:29.872+0000] {cassandra.py:128} WARNING - Downgrading core protocol version from 65 to 5 for 172.21.0.4:9042. To avoid this, it is best practice to explicitly set Cluster(protocol_version) to the version supported by your cluster. http://datastax.github.io/python-driver/api/cassandra/cluster.html#cassandra.cluster.Cluster.protocol_version
[2024-04-08T15:00:30.281+0000] {record.py:71} INFO - Sensor check existence of record: ['user_id', 'age', 'email', 'name']
[2024-04-08T15:00:30.387+0000] {base.py:83} INFO - Using connection ID 'cassandra_conn' for task execution.
[2024-04-08T15:00:30.406+0000] {cassandra.py:128} WARNING - Downgrading core protocol version from 66 to 65 for 172.21.0.4:9042. To avoid this, it is best practice to explicitly set Cluster(protocol_version) to the version supported by your cluster. http://datastax.github.io/python-driver/api/cassandra/cluster.html#cassandra.cluster.Cluster.protocol_version
[2024-04-08T15:00:30.418+0000] {cassandra.py:128} WARNING - Downgrading core protocol version from 65 to 5 for 172.21.0.4:9042. To avoid this, it is best practice to explicitly set Cluster(protocol_version) to the version supported by your cluster. http://datastax.github.io/python-driver/api/cassandra/cluster.html#cassandra.cluster.Cluster.protocol_version
[2024-04-08T15:01:30.900+0000] {record.py:71} INFO - Sensor check existence of record: ['user_id', 'age', 'email', 'name']
[2024-04-08T15:01:30.998+0000] {base.py:83} INFO - Using connection ID 'cassandra_conn' for task execution.
[2024-04-08T15:01:31.108+0000] {cassandra.py:128} WARNING - Downgrading core protocol version from 66 to 65 for 172.21.0.4:9042. To avoid this, it is best practice to explicitly set Cluster(protocol_version) to the version supported by your cluster. http://datastax.github.io/python-driver/api/cassandra/cluster.html#cassandra.cluster.Cluster.protocol_version
[2024-04-08T15:01:31.141+0000] {cassandra.py:128} WARNING - Downgrading core protocol version from 65 to 5 for 172.21.0.4:9042. To avoid this, it is best practice to explicitly set Cluster(protocol_version) to the version supported by your cluster. http://datastax.github.io/python-driver/api/cassandra/cluster.html#cassandra.cluster.Cluster.protocol_version
[2024-04-08T15:02:32.072+0000] {record.py:71} INFO - Sensor check existence of record: ['user_id', 'age', 'email', 'name']
[2024-04-08T15:02:32.131+0000] {base.py:83} INFO - Using connection ID 'cassandra_conn' for task execution.
[2024-04-08T15:02:32.154+0000] {cassandra.py:128} WARNING - Downgrading core protocol version from 66 to 65 for 172.21.0.4:9042. To avoid this, it is best practice to explicitly set Cluster(protocol_version) to the version supported by your cluster. http://datastax.github.io/python-driver/api/cassandra/cluster.html#cassandra.cluster.Cluster.protocol_version
[2024-04-08T15:02:32.164+0000] {cassandra.py:128} WARNING - Downgrading core protocol version from 65 to 5 for 172.21.0.4:9042. To avoid this, it is best practice to explicitly set Cluster(protocol_version) to the version supported by your cluster. http://datastax.github.io/python-driver/api/cassandra/cluster.html#cassandra.cluster.Cluster.protocol_version
[2024-04-08T15:02:52.192+0000] {local_task_job_runner.py:302} WARNING - State of this instance has been externally set to None. Terminating instance.
[2024-04-08T15:02:52.254+0000] {process_utils.py:131} INFO - Sending 15 to group 1129. PIDs of all processes in the group: [1129]
[2024-04-08T15:02:52.263+0000] {process_utils.py:86} INFO - Sending the signal 15 to group 1129
[2024-04-08T15:02:52.268+0000] {taskinstance.py:2483} ERROR - Received SIGTERM. Terminating subprocesses.
[2024-04-08T15:02:52.362+0000] {taskinstance.py:2731} ERROR - Task failed with exception
Traceback (most recent call last):
  File "/home/airflow/.local/lib/python3.8/site-packages/airflow/models/taskinstance.py", line 444, in _execute_task
    result = _execute_callable(context=context, **execute_callable_kwargs)
  File "/home/airflow/.local/lib/python3.8/site-packages/airflow/models/taskinstance.py", line 414, in _execute_callable
    return execute_callable(context=context, **execute_callable_kwargs)
  File "/home/airflow/.local/lib/python3.8/site-packages/airflow/sensors/base.py", line 293, in execute
    time.sleep(self._get_next_poke_interval(started_at, run_duration, try_number))
  File "/home/airflow/.local/lib/python3.8/site-packages/airflow/models/taskinstance.py", line 2485, in signal_handler
    raise AirflowException("Task received SIGTERM signal")
airflow.exceptions.AirflowException: Task received SIGTERM signal
[2024-04-08T15:02:52.386+0000] {taskinstance.py:1149} INFO - Marking task as FAILED. dag_id=cassandra_sensor_dag, task_id=cassandra_sensor_record, execution_date=20240408T002500, start_date=20240408T145823, end_date=20240408T150252
[2024-04-08T15:02:52.551+0000] {standard_task_runner.py:107} ERROR - Failed to execute job 108 for task cassandra_sensor_record ((psycopg2.errors.ForeignKeyViolation) insert or update on table "task_fail" violates foreign key constraint "task_fail_ti_fkey"
DETAIL:  Key (dag_id, task_id, run_id, map_index)=(cassandra_sensor_dag, cassandra_sensor_record, scheduled__2024-04-08T00:25:00+00:00, -1) is not present in table "task_instance".

[SQL: INSERT INTO task_fail (task_id, dag_id, run_id, map_index, start_date, end_date, duration) VALUES (%(task_id)s, %(dag_id)s, %(run_id)s, %(map_index)s, %(start_date)s, %(end_date)s, %(duration)s) RETURNING task_fail.id]
[parameters: {'task_id': 'cassandra_sensor_record', 'dag_id': 'cassandra_sensor_dag', 'run_id': 'scheduled__2024-04-08T00:25:00+00:00', 'map_index': -1, 'start_date': datetime.datetime(2024, 4, 8, 14, 58, 23, 191574, tzinfo=Timezone('UTC')), 'end_date': datetime.datetime(2024, 4, 8, 15, 2, 52, 379953, tzinfo=Timezone('UTC')), 'duration': 269}]
(Background on this error at: https://sqlalche.me/e/14/gkpj); 1129)
[2024-04-08T15:02:52.673+0000] {process_utils.py:79} INFO - Process psutil.Process(pid=1129, status='terminated', exitcode=1, started='14:58:23') (1129) terminated with exit code 1
[2024-04-08T15:04:28.802+0000] {taskinstance.py:1979} INFO - Dependencies all met for dep_context=non-requeueable deps ti=<TaskInstance: cassandra_sensor_dag.cassandra_sensor_record scheduled__2024-04-08T00:25:00+00:00 [queued]>
[2024-04-08T15:04:29.090+0000] {taskinstance.py:1979} INFO - Dependencies all met for dep_context=requeueable deps ti=<TaskInstance: cassandra_sensor_dag.cassandra_sensor_record scheduled__2024-04-08T00:25:00+00:00 [queued]>
[2024-04-08T15:04:29.104+0000] {taskinstance.py:2193} INFO - Starting attempt 1 of 2
[2024-04-08T15:04:29.673+0000] {taskinstance.py:2217} INFO - Executing <Task(CassandraRecordSensor): cassandra_sensor_record> on 2024-04-08 00:25:00+00:00
[2024-04-08T15:04:29.760+0000] {standard_task_runner.py:60} INFO - Started process 1575 to run task
[2024-04-08T15:04:29.837+0000] {standard_task_runner.py:87} INFO - Running: ['***', 'tasks', 'run', 'cassandra_sensor_dag', 'cassandra_sensor_record', 'scheduled__2024-04-08T00:25:00+00:00', '--job-id', '128', '--raw', '--subdir', 'DAGS_FOLDER/test.py', '--cfg-path', '/tmp/tmpctqhmk8h']
[2024-04-08T15:04:29.901+0000] {standard_task_runner.py:88} INFO - Job 128: Subtask cassandra_sensor_record
[2024-04-08T15:04:30.997+0000] {task_command.py:423} INFO - Running <TaskInstance: cassandra_sensor_dag.cassandra_sensor_record scheduled__2024-04-08T00:25:00+00:00 [running]> on host c2d2cc8ff432
[2024-04-08T15:04:32.527+0000] {taskinstance.py:2513} INFO - Exporting env vars: AIRFLOW_CTX_DAG_OWNER='***' AIRFLOW_CTX_DAG_ID='cassandra_sensor_dag' AIRFLOW_CTX_TASK_ID='cassandra_sensor_record' AIRFLOW_CTX_EXECUTION_DATE='2024-04-08T00:25:00+00:00' AIRFLOW_CTX_TRY_NUMBER='1' AIRFLOW_CTX_DAG_RUN_ID='scheduled__2024-04-08T00:25:00+00:00'
[2024-04-08T15:04:32.559+0000] {record.py:71} INFO - Sensor check existence of record: ['user_id', 'age', 'email', 'name']
[2024-04-08T15:04:32.786+0000] {base.py:83} INFO - Using connection ID 'cassandra_conn' for task execution.
[2024-04-08T15:04:32.824+0000] {warnings.py:109} WARNING - /home/***/.local/lib/python3.8/site-packages/***/providers/apache/cassandra/hooks/cassandra.py:120: DeprecationWarning: Legacy execution parameters will be removed in 4.0. Consider using execution profiles.
  self.cluster = Cluster(**conn_config)

[2024-04-08T15:04:32.895+0000] {cassandra.py:128} WARNING - Downgrading core protocol version from 66 to 65 for 172.21.0.4:9042. To avoid this, it is best practice to explicitly set Cluster(protocol_version) to the version supported by your cluster. http://datastax.github.io/python-driver/api/cassandra/cluster.html#cassandra.cluster.Cluster.protocol_version
[2024-04-08T15:04:32.922+0000] {cassandra.py:128} WARNING - Downgrading core protocol version from 65 to 5 for 172.21.0.4:9042. To avoid this, it is best practice to explicitly set Cluster(protocol_version) to the version supported by your cluster. http://datastax.github.io/python-driver/api/cassandra/cluster.html#cassandra.cluster.Cluster.protocol_version
[2024-04-08T15:05:33.501+0000] {record.py:71} INFO - Sensor check existence of record: ['user_id', 'age', 'email', 'name']
[2024-04-08T15:05:33.514+0000] {base.py:83} INFO - Using connection ID 'cassandra_conn' for task execution.
[2024-04-08T15:05:33.523+0000] {cassandra.py:128} WARNING - Downgrading core protocol version from 66 to 65 for 172.21.0.4:9042. To avoid this, it is best practice to explicitly set Cluster(protocol_version) to the version supported by your cluster. http://datastax.github.io/python-driver/api/cassandra/cluster.html#cassandra.cluster.Cluster.protocol_version
[2024-04-08T15:05:33.526+0000] {cassandra.py:128} WARNING - Downgrading core protocol version from 65 to 5 for 172.21.0.4:9042. To avoid this, it is best practice to explicitly set Cluster(protocol_version) to the version supported by your cluster. http://datastax.github.io/python-driver/api/cassandra/cluster.html#cassandra.cluster.Cluster.protocol_version
[2024-04-08T15:06:33.666+0000] {record.py:71} INFO - Sensor check existence of record: ['user_id', 'age', 'email', 'name']
[2024-04-08T15:06:33.691+0000] {base.py:83} INFO - Using connection ID 'cassandra_conn' for task execution.
[2024-04-08T15:06:33.698+0000] {cassandra.py:128} WARNING - Downgrading core protocol version from 66 to 65 for 172.21.0.4:9042. To avoid this, it is best practice to explicitly set Cluster(protocol_version) to the version supported by your cluster. http://datastax.github.io/python-driver/api/cassandra/cluster.html#cassandra.cluster.Cluster.protocol_version
[2024-04-08T15:06:33.701+0000] {cassandra.py:128} WARNING - Downgrading core protocol version from 65 to 5 for 172.21.0.4:9042. To avoid this, it is best practice to explicitly set Cluster(protocol_version) to the version supported by your cluster. http://datastax.github.io/python-driver/api/cassandra/cluster.html#cassandra.cluster.Cluster.protocol_version
[2024-04-08T15:07:33.907+0000] {record.py:71} INFO - Sensor check existence of record: ['user_id', 'age', 'email', 'name']
[2024-04-08T15:07:33.947+0000] {base.py:83} INFO - Using connection ID 'cassandra_conn' for task execution.
[2024-04-08T15:07:34.028+0000] {cassandra.py:128} WARNING - Downgrading core protocol version from 66 to 65 for 172.21.0.4:9042. To avoid this, it is best practice to explicitly set Cluster(protocol_version) to the version supported by your cluster. http://datastax.github.io/python-driver/api/cassandra/cluster.html#cassandra.cluster.Cluster.protocol_version
[2024-04-08T15:07:34.037+0000] {cassandra.py:128} WARNING - Downgrading core protocol version from 65 to 5 for 172.21.0.4:9042. To avoid this, it is best practice to explicitly set Cluster(protocol_version) to the version supported by your cluster. http://datastax.github.io/python-driver/api/cassandra/cluster.html#cassandra.cluster.Cluster.protocol_version
[2024-04-08T15:08:34.760+0000] {record.py:71} INFO - Sensor check existence of record: ['user_id', 'age', 'email', 'name']
[2024-04-08T15:08:34.821+0000] {base.py:83} INFO - Using connection ID 'cassandra_conn' for task execution.
[2024-04-08T15:08:34.832+0000] {cassandra.py:128} WARNING - Downgrading core protocol version from 66 to 65 for 172.21.0.4:9042. To avoid this, it is best practice to explicitly set Cluster(protocol_version) to the version supported by your cluster. http://datastax.github.io/python-driver/api/cassandra/cluster.html#cassandra.cluster.Cluster.protocol_version
[2024-04-08T15:08:34.839+0000] {cassandra.py:128} WARNING - Downgrading core protocol version from 65 to 5 for 172.21.0.4:9042. To avoid this, it is best practice to explicitly set Cluster(protocol_version) to the version supported by your cluster. http://datastax.github.io/python-driver/api/cassandra/cluster.html#cassandra.cluster.Cluster.protocol_version
[2024-04-08T15:09:35.110+0000] {record.py:71} INFO - Sensor check existence of record: ['user_id', 'age', 'email', 'name']
[2024-04-08T15:09:35.015+0000] {job.py:213} ERROR - Job heartbeat got an exception
Traceback (most recent call last):
  File "/home/airflow/.local/lib/python3.8/site-packages/sqlalchemy/engine/base.py", line 3371, in _wrap_pool_connect
    return fn()
  File "/home/airflow/.local/lib/python3.8/site-packages/sqlalchemy/pool/base.py", line 327, in connect
    return _ConnectionFairy._checkout(self)
  File "/home/airflow/.local/lib/python3.8/site-packages/sqlalchemy/pool/base.py", line 894, in _checkout
    fairy = _ConnectionRecord.checkout(pool)
  File "/home/airflow/.local/lib/python3.8/site-packages/sqlalchemy/pool/base.py", line 493, in checkout
    rec = pool._do_get()
  File "/home/airflow/.local/lib/python3.8/site-packages/sqlalchemy/pool/impl.py", line 256, in _do_get
    return self._create_connection()
  File "/home/airflow/.local/lib/python3.8/site-packages/sqlalchemy/pool/base.py", line 273, in _create_connection
    return _ConnectionRecord(self)
  File "/home/airflow/.local/lib/python3.8/site-packages/sqlalchemy/pool/base.py", line 388, in __init__
    self.__connect()
  File "/home/airflow/.local/lib/python3.8/site-packages/sqlalchemy/pool/base.py", line 691, in __connect
    pool.logger.debug("Error on connect(): %s", e)
  File "/home/airflow/.local/lib/python3.8/site-packages/sqlalchemy/util/langhelpers.py", line 70, in __exit__
    compat.raise_(
  File "/home/airflow/.local/lib/python3.8/site-packages/sqlalchemy/util/compat.py", line 211, in raise_
    raise exception
  File "/home/airflow/.local/lib/python3.8/site-packages/sqlalchemy/pool/base.py", line 686, in __connect
    self.dbapi_connection = connection = pool._invoke_creator(self)
  File "/home/airflow/.local/lib/python3.8/site-packages/sqlalchemy/engine/create.py", line 574, in connect
    return dialect.connect(*cargs, **cparams)
  File "/home/airflow/.local/lib/python3.8/site-packages/sqlalchemy/engine/default.py", line 598, in connect
    return self.dbapi.connect(*cargs, **cparams)
  File "/home/airflow/.local/lib/python3.8/site-packages/psycopg2/__init__.py", line 122, in connect
    conn = _connect(dsn, connection_factory=connection_factory, **kwasync)
psycopg2.OperationalError: could not translate host name "postgres" to address: Temporary failure in name resolution


The above exception was the direct cause of the following exception:

Traceback (most recent call last):
  File "/home/airflow/.local/lib/python3.8/site-packages/airflow/jobs/job.py", line 187, in heartbeat
    self._merge_from(Job._fetch_from_db(self, session))
  File "/home/airflow/.local/lib/python3.8/site-packages/airflow/api_internal/internal_api_call.py", line 114, in wrapper
    return func(*args, **kwargs)
  File "/home/airflow/.local/lib/python3.8/site-packages/airflow/utils/session.py", line 76, in wrapper
    return func(*args, **kwargs)
  File "/home/airflow/.local/lib/python3.8/site-packages/airflow/jobs/job.py", line 310, in _fetch_from_db
    session.merge(job)
  File "/home/airflow/.local/lib/python3.8/site-packages/sqlalchemy/orm/session.py", line 3056, in merge
    return self._merge(
  File "/home/airflow/.local/lib/python3.8/site-packages/sqlalchemy/orm/session.py", line 3136, in _merge
    merged = self.get(
  File "/home/airflow/.local/lib/python3.8/site-packages/sqlalchemy/orm/session.py", line 2853, in get
    return self._get_impl(
  File "/home/airflow/.local/lib/python3.8/site-packages/sqlalchemy/orm/session.py", line 2975, in _get_impl
    return db_load_fn(
  File "/home/airflow/.local/lib/python3.8/site-packages/sqlalchemy/orm/loading.py", line 530, in load_on_pk_identity
    session.execute(
  File "/home/airflow/.local/lib/python3.8/site-packages/sqlalchemy/orm/session.py", line 1716, in execute
    conn = self._connection_for_bind(bind)
  File "/home/airflow/.local/lib/python3.8/site-packages/sqlalchemy/orm/session.py", line 1555, in _connection_for_bind
    return self._transaction._connection_for_bind(
  File "/home/airflow/.local/lib/python3.8/site-packages/sqlalchemy/orm/session.py", line 750, in _connection_for_bind
    conn = bind.connect()
  File "/home/airflow/.local/lib/python3.8/site-packages/sqlalchemy/future/engine.py", line 412, in connect
    return super(Engine, self).connect()
  File "/home/airflow/.local/lib/python3.8/site-packages/sqlalchemy/engine/base.py", line 3325, in connect
    return self._connection_cls(self, close_with_result=close_with_result)
  File "/home/airflow/.local/lib/python3.8/site-packages/sqlalchemy/engine/base.py", line 96, in __init__
    else engine.raw_connection()
  File "/home/airflow/.local/lib/python3.8/site-packages/sqlalchemy/engine/base.py", line 3404, in raw_connection
    return self._wrap_pool_connect(self.pool.connect, _connection)
  File "/home/airflow/.local/lib/python3.8/site-packages/sqlalchemy/engine/base.py", line 3374, in _wrap_pool_connect
    Connection._handle_dbapi_exception_noconnection(
  File "/home/airflow/.local/lib/python3.8/site-packages/sqlalchemy/engine/base.py", line 2208, in _handle_dbapi_exception_noconnection
    util.raise_(
  File "/home/airflow/.local/lib/python3.8/site-packages/sqlalchemy/util/compat.py", line 211, in raise_
    raise exception
  File "/home/airflow/.local/lib/python3.8/site-packages/sqlalchemy/engine/base.py", line 3371, in _wrap_pool_connect
    return fn()
  File "/home/airflow/.local/lib/python3.8/site-packages/sqlalchemy/pool/base.py", line 327, in connect
    return _ConnectionFairy._checkout(self)
  File "/home/airflow/.local/lib/python3.8/site-packages/sqlalchemy/pool/base.py", line 894, in _checkout
    fairy = _ConnectionRecord.checkout(pool)
  File "/home/airflow/.local/lib/python3.8/site-packages/sqlalchemy/pool/base.py", line 493, in checkout
    rec = pool._do_get()
  File "/home/airflow/.local/lib/python3.8/site-packages/sqlalchemy/pool/impl.py", line 256, in _do_get
    return self._create_connection()
  File "/home/airflow/.local/lib/python3.8/site-packages/sqlalchemy/pool/base.py", line 273, in _create_connection
    return _ConnectionRecord(self)
  File "/home/airflow/.local/lib/python3.8/site-packages/sqlalchemy/pool/base.py", line 388, in __init__
    self.__connect()
  File "/home/airflow/.local/lib/python3.8/site-packages/sqlalchemy/pool/base.py", line 691, in __connect
    pool.logger.debug("Error on connect(): %s", e)
  File "/home/airflow/.local/lib/python3.8/site-packages/sqlalchemy/util/langhelpers.py", line 70, in __exit__
    compat.raise_(
  File "/home/airflow/.local/lib/python3.8/site-packages/sqlalchemy/util/compat.py", line 211, in raise_
    raise exception
  File "/home/airflow/.local/lib/python3.8/site-packages/sqlalchemy/pool/base.py", line 686, in __connect
    self.dbapi_connection = connection = pool._invoke_creator(self)
  File "/home/airflow/.local/lib/python3.8/site-packages/sqlalchemy/engine/create.py", line 574, in connect
    return dialect.connect(*cargs, **cparams)
  File "/home/airflow/.local/lib/python3.8/site-packages/sqlalchemy/engine/default.py", line 598, in connect
    return self.dbapi.connect(*cargs, **cparams)
  File "/home/airflow/.local/lib/python3.8/site-packages/psycopg2/__init__.py", line 122, in connect
    conn = _connect(dsn, connection_factory=connection_factory, **kwasync)
sqlalchemy.exc.OperationalError: (psycopg2.OperationalError) could not translate host name "postgres" to address: Temporary failure in name resolution

(Background on this error at: https://sqlalche.me/e/14/e3q8)
[2024-04-08T15:11:28.848+0000] {threading.py:932} WARNING - Heartbeat failed for connection (140560700594544) to 172.21.0.4:9042
[2024-04-08T15:11:28.890+0000] {job.py:221} ERROR - Job heartbeat failed with error. Scheduler is in unhealthy state
[2024-04-08T15:11:28.903+0000] {connection.py:508} ERROR - Unable to retrieve connection from secrets backend (MetastoreBackend). Checking subsequent secrets backend.
Traceback (most recent call last):
  File "/home/airflow/.local/lib/python3.8/site-packages/sqlalchemy/engine/base.py", line 3371, in _wrap_pool_connect
    return fn()
  File "/home/airflow/.local/lib/python3.8/site-packages/sqlalchemy/pool/base.py", line 327, in connect
    return _ConnectionFairy._checkout(self)
  File "/home/airflow/.local/lib/python3.8/site-packages/sqlalchemy/pool/base.py", line 894, in _checkout
    fairy = _ConnectionRecord.checkout(pool)
  File "/home/airflow/.local/lib/python3.8/site-packages/sqlalchemy/pool/base.py", line 493, in checkout
    rec = pool._do_get()
  File "/home/airflow/.local/lib/python3.8/site-packages/sqlalchemy/pool/impl.py", line 256, in _do_get
    return self._create_connection()
  File "/home/airflow/.local/lib/python3.8/site-packages/sqlalchemy/pool/base.py", line 273, in _create_connection
    return _ConnectionRecord(self)
  File "/home/airflow/.local/lib/python3.8/site-packages/sqlalchemy/pool/base.py", line 388, in __init__
    self.__connect()
  File "/home/airflow/.local/lib/python3.8/site-packages/sqlalchemy/pool/base.py", line 691, in __connect
    pool.logger.debug("Error on connect(): %s", e)
  File "/home/airflow/.local/lib/python3.8/site-packages/sqlalchemy/util/langhelpers.py", line 70, in __exit__
    compat.raise_(
  File "/home/airflow/.local/lib/python3.8/site-packages/sqlalchemy/util/compat.py", line 211, in raise_
    raise exception
  File "/home/airflow/.local/lib/python3.8/site-packages/sqlalchemy/pool/base.py", line 686, in __connect
    self.dbapi_connection = connection = pool._invoke_creator(self)
  File "/home/airflow/.local/lib/python3.8/site-packages/sqlalchemy/engine/create.py", line 574, in connect
    return dialect.connect(*cargs, **cparams)
  File "/home/airflow/.local/lib/python3.8/site-packages/sqlalchemy/engine/default.py", line 598, in connect
    return self.dbapi.connect(*cargs, **cparams)
  File "/home/airflow/.local/lib/python3.8/site-packages/psycopg2/__init__.py", line 122, in connect
    conn = _connect(dsn, connection_factory=connection_factory, **kwasync)
psycopg2.OperationalError: could not translate host name "postgres" to address: Temporary failure in name resolution


The above exception was the direct cause of the following exception:

Traceback (most recent call last):
  File "/home/airflow/.local/lib/python3.8/site-packages/airflow/models/connection.py", line 503, in get_connection_from_secrets
    conn = secrets_backend.get_connection(conn_id=conn_id)
  File "/home/airflow/.local/lib/python3.8/site-packages/airflow/utils/session.py", line 79, in wrapper
    return func(*args, session=session, **kwargs)
  File "/home/airflow/.local/lib/python3.8/site-packages/airflow/secrets/metastore.py", line 42, in get_connection
    return MetastoreBackend._fetch_connection(conn_id, session=session)
  File "/home/airflow/.local/lib/python3.8/site-packages/airflow/api_internal/internal_api_call.py", line 114, in wrapper
    return func(*args, **kwargs)
  File "/home/airflow/.local/lib/python3.8/site-packages/airflow/utils/session.py", line 76, in wrapper
    return func(*args, **kwargs)
  File "/home/airflow/.local/lib/python3.8/site-packages/airflow/secrets/metastore.py", line 73, in _fetch_connection
    conn = session.scalar(select(Connection).where(Connection.conn_id == conn_id).limit(1))
  File "/home/airflow/.local/lib/python3.8/site-packages/sqlalchemy/orm/session.py", line 1747, in scalar
    return self.execute(
  File "/home/airflow/.local/lib/python3.8/site-packages/sqlalchemy/orm/session.py", line 1716, in execute
    conn = self._connection_for_bind(bind)
  File "/home/airflow/.local/lib/python3.8/site-packages/sqlalchemy/orm/session.py", line 1555, in _connection_for_bind
    return self._transaction._connection_for_bind(
  File "/home/airflow/.local/lib/python3.8/site-packages/sqlalchemy/orm/session.py", line 750, in _connection_for_bind
    conn = bind.connect()
  File "/home/airflow/.local/lib/python3.8/site-packages/sqlalchemy/future/engine.py", line 412, in connect
    return super(Engine, self).connect()
  File "/home/airflow/.local/lib/python3.8/site-packages/sqlalchemy/engine/base.py", line 3325, in connect
    return self._connection_cls(self, close_with_result=close_with_result)
  File "/home/airflow/.local/lib/python3.8/site-packages/sqlalchemy/engine/base.py", line 96, in __init__
    else engine.raw_connection()
  File "/home/airflow/.local/lib/python3.8/site-packages/sqlalchemy/engine/base.py", line 3404, in raw_connection
    return self._wrap_pool_connect(self.pool.connect, _connection)
  File "/home/airflow/.local/lib/python3.8/site-packages/sqlalchemy/engine/base.py", line 3374, in _wrap_pool_connect
    Connection._handle_dbapi_exception_noconnection(
  File "/home/airflow/.local/lib/python3.8/site-packages/sqlalchemy/engine/base.py", line 2208, in _handle_dbapi_exception_noconnection
    util.raise_(
  File "/home/airflow/.local/lib/python3.8/site-packages/sqlalchemy/util/compat.py", line 211, in raise_
    raise exception
  File "/home/airflow/.local/lib/python3.8/site-packages/sqlalchemy/engine/base.py", line 3371, in _wrap_pool_connect
    return fn()
  File "/home/airflow/.local/lib/python3.8/site-packages/sqlalchemy/pool/base.py", line 327, in connect
    return _ConnectionFairy._checkout(self)
  File "/home/airflow/.local/lib/python3.8/site-packages/sqlalchemy/pool/base.py", line 894, in _checkout
    fairy = _ConnectionRecord.checkout(pool)
  File "/home/airflow/.local/lib/python3.8/site-packages/sqlalchemy/pool/base.py", line 493, in checkout
    rec = pool._do_get()
  File "/home/airflow/.local/lib/python3.8/site-packages/sqlalchemy/pool/impl.py", line 256, in _do_get
    return self._create_connection()
  File "/home/airflow/.local/lib/python3.8/site-packages/sqlalchemy/pool/base.py", line 273, in _create_connection
    return _ConnectionRecord(self)
  File "/home/airflow/.local/lib/python3.8/site-packages/sqlalchemy/pool/base.py", line 388, in __init__
    self.__connect()
  File "/home/airflow/.local/lib/python3.8/site-packages/sqlalchemy/pool/base.py", line 691, in __connect
    pool.logger.debug("Error on connect(): %s", e)
  File "/home/airflow/.local/lib/python3.8/site-packages/sqlalchemy/util/langhelpers.py", line 70, in __exit__
    compat.raise_(
  File "/home/airflow/.local/lib/python3.8/site-packages/sqlalchemy/util/compat.py", line 211, in raise_
    raise exception
  File "/home/airflow/.local/lib/python3.8/site-packages/sqlalchemy/pool/base.py", line 686, in __connect
    self.dbapi_connection = connection = pool._invoke_creator(self)
  File "/home/airflow/.local/lib/python3.8/site-packages/sqlalchemy/engine/create.py", line 574, in connect
    return dialect.connect(*cargs, **cparams)
  File "/home/airflow/.local/lib/python3.8/site-packages/sqlalchemy/engine/default.py", line 598, in connect
    return self.dbapi.connect(*cargs, **cparams)
  File "/home/airflow/.local/lib/python3.8/site-packages/psycopg2/__init__.py", line 122, in connect
    conn = _connect(dsn, connection_factory=connection_factory, **kwasync)
sqlalchemy.exc.OperationalError: (psycopg2.OperationalError) could not translate host name "postgres" to address: Temporary failure in name resolution

(Background on this error at: https://sqlalche.me/e/14/e3q8)
[2024-04-08T15:11:28.907+0000] {threading.py:932} WARNING - Heartbeat failed for connection (140560674833888) to 172.21.0.4:9042
[2024-04-08T15:11:28.907+0000] {threading.py:932} WARNING - Heartbeat failed for connection (140560710342112) to 172.21.0.4:9042
[2024-04-08T15:11:28.935+0000] {threading.py:932} WARNING - Heartbeat failed for connection (140560710256432) to 172.21.0.4:9042
[2024-04-08T15:11:28.958+0000] {threading.py:932} WARNING - Heartbeat failed for connection (140560711121696) to 172.21.0.4:9042
[2024-04-08T15:11:28.944+0000] {thread.py:57} WARNING - [control connection] Error connecting to 172.21.0.4:9042:
Traceback (most recent call last):
  File "cassandra/cluster.py", line 3577, in cassandra.cluster.ControlConnection._reconnect_internal
  File "cassandra/cluster.py", line 3599, in cassandra.cluster.ControlConnection._try_connect
  File "cassandra/cluster.py", line 1670, in cassandra.cluster.Cluster.connection_factory
  File "cassandra/connection.py", line 846, in cassandra.connection.Connection.factory
  File "/home/airflow/.local/lib/python3.8/site-packages/cassandra/io/libevreactor.py", line 266, in __init__
    self._connect_socket()
  File "cassandra/connection.py", line 951, in cassandra.connection.Connection._connect_socket
ConnectionRefusedError: [Errno 111] Tried connecting to [('172.21.0.4', 9042)]. Last error: Connection refused
[2024-04-08T15:11:29.001+0000] {thread.py:57} WARNING - [control connection] Error connecting to 172.21.0.4:9042:
Traceback (most recent call last):
  File "cassandra/cluster.py", line 3577, in cassandra.cluster.ControlConnection._reconnect_internal
  File "cassandra/cluster.py", line 3599, in cassandra.cluster.ControlConnection._try_connect
  File "cassandra/cluster.py", line 1670, in cassandra.cluster.Cluster.connection_factory
  File "cassandra/connection.py", line 846, in cassandra.connection.Connection.factory
  File "/home/airflow/.local/lib/python3.8/site-packages/cassandra/io/libevreactor.py", line 266, in __init__
    self._connect_socket()
  File "cassandra/connection.py", line 951, in cassandra.connection.Connection._connect_socket
ConnectionRefusedError: [Errno 111] Tried connecting to [('172.21.0.4', 9042)]. Last error: Connection refused
[2024-04-08T15:11:29.162+0000] {thread.py:57} WARNING - [control connection] Error connecting to 172.21.0.4:9042:
Traceback (most recent call last):
  File "cassandra/cluster.py", line 3577, in cassandra.cluster.ControlConnection._reconnect_internal
  File "cassandra/cluster.py", line 3599, in cassandra.cluster.ControlConnection._try_connect
  File "cassandra/cluster.py", line 1670, in cassandra.cluster.Cluster.connection_factory
  File "cassandra/connection.py", line 846, in cassandra.connection.Connection.factory
  File "/home/airflow/.local/lib/python3.8/site-packages/cassandra/io/libevreactor.py", line 266, in __init__
    self._connect_socket()
  File "cassandra/connection.py", line 951, in cassandra.connection.Connection._connect_socket
ConnectionRefusedError: [Errno 111] Tried connecting to [('172.21.0.4', 9042)]. Last error: Connection refused
[2024-04-08T15:11:29.166+0000] {thread.py:57} WARNING - [control connection] Error connecting to 172.21.0.4:9042:
Traceback (most recent call last):
  File "cassandra/cluster.py", line 3577, in cassandra.cluster.ControlConnection._reconnect_internal
  File "cassandra/cluster.py", line 3599, in cassandra.cluster.ControlConnection._try_connect
  File "cassandra/cluster.py", line 1670, in cassandra.cluster.Cluster.connection_factory
  File "cassandra/connection.py", line 846, in cassandra.connection.Connection.factory
  File "/home/airflow/.local/lib/python3.8/site-packages/cassandra/io/libevreactor.py", line 266, in __init__
    self._connect_socket()
  File "cassandra/connection.py", line 951, in cassandra.connection.Connection._connect_socket
ConnectionRefusedError: [Errno 111] Tried connecting to [('172.21.0.4', 9042)]. Last error: Connection refused
[2024-04-08T15:11:29.171+0000] {thread.py:57} WARNING - [control connection] Error connecting to 172.21.0.4:9042:
Traceback (most recent call last):
  File "cassandra/cluster.py", line 3577, in cassandra.cluster.ControlConnection._reconnect_internal
  File "cassandra/cluster.py", line 3599, in cassandra.cluster.ControlConnection._try_connect
  File "cassandra/cluster.py", line 1670, in cassandra.cluster.Cluster.connection_factory
  File "cassandra/connection.py", line 846, in cassandra.connection.Connection.factory
  File "/home/airflow/.local/lib/python3.8/site-packages/cassandra/io/libevreactor.py", line 266, in __init__
    self._connect_socket()
  File "cassandra/connection.py", line 951, in cassandra.connection.Connection._connect_socket
ConnectionRefusedError: [Errno 111] Tried connecting to [('172.21.0.4', 9042)]. Last error: Connection refused
[2024-04-08T15:11:29.250+0000] {thread.py:57} WARNING - [control connection] Error connecting to 172.21.0.4:9042:
Traceback (most recent call last):
  File "cassandra/cluster.py", line 3577, in cassandra.cluster.ControlConnection._reconnect_internal
  File "cassandra/cluster.py", line 3599, in cassandra.cluster.ControlConnection._try_connect
  File "cassandra/cluster.py", line 1670, in cassandra.cluster.Cluster.connection_factory
  File "cassandra/connection.py", line 846, in cassandra.connection.Connection.factory
  File "/home/airflow/.local/lib/python3.8/site-packages/cassandra/io/libevreactor.py", line 266, in __init__
    self._connect_socket()
  File "cassandra/connection.py", line 951, in cassandra.connection.Connection._connect_socket
ConnectionRefusedError: [Errno 111] Tried connecting to [('172.21.0.4', 9042)]. Last error: Connection refused
[2024-04-08T15:11:29.253+0000] {thread.py:57} WARNING - [control connection] Error connecting to 172.21.0.4:9042:
Traceback (most recent call last):
  File "cassandra/cluster.py", line 3577, in cassandra.cluster.ControlConnection._reconnect_internal
  File "cassandra/cluster.py", line 3599, in cassandra.cluster.ControlConnection._try_connect
  File "cassandra/cluster.py", line 1670, in cassandra.cluster.Cluster.connection_factory
  File "cassandra/connection.py", line 846, in cassandra.connection.Connection.factory
  File "/home/airflow/.local/lib/python3.8/site-packages/cassandra/io/libevreactor.py", line 266, in __init__
    self._connect_socket()
  File "cassandra/connection.py", line 951, in cassandra.connection.Connection._connect_socket
ConnectionRefusedError: [Errno 111] Tried connecting to [('172.21.0.4', 9042)]. Last error: Connection refused
[2024-04-08T15:11:29.257+0000] {thread.py:57} WARNING - [control connection] Error connecting to 172.21.0.4:9042:
Traceback (most recent call last):
  File "cassandra/cluster.py", line 3577, in cassandra.cluster.ControlConnection._reconnect_internal
  File "cassandra/cluster.py", line 3599, in cassandra.cluster.ControlConnection._try_connect
  File "cassandra/cluster.py", line 1670, in cassandra.cluster.Cluster.connection_factory
  File "cassandra/connection.py", line 846, in cassandra.connection.Connection.factory
  File "/home/airflow/.local/lib/python3.8/site-packages/cassandra/io/libevreactor.py", line 266, in __init__
    self._connect_socket()
  File "cassandra/connection.py", line 951, in cassandra.connection.Connection._connect_socket
ConnectionRefusedError: [Errno 111] Tried connecting to [('172.21.0.4', 9042)]. Last error: Connection refused
[2024-04-08T15:11:30.320+0000] {thread.py:57} WARNING - [control connection] Error connecting to 172.21.0.4:9042:
Traceback (most recent call last):
  File "cassandra/cluster.py", line 3577, in cassandra.cluster.ControlConnection._reconnect_internal
  File "cassandra/cluster.py", line 3599, in cassandra.cluster.ControlConnection._try_connect
  File "cassandra/cluster.py", line 1670, in cassandra.cluster.Cluster.connection_factory
  File "cassandra/connection.py", line 846, in cassandra.connection.Connection.factory
  File "/home/airflow/.local/lib/python3.8/site-packages/cassandra/io/libevreactor.py", line 266, in __init__
    self._connect_socket()
  File "cassandra/connection.py", line 951, in cassandra.connection.Connection._connect_socket
ConnectionRefusedError: [Errno 111] Tried connecting to [('172.21.0.4', 9042)]. Last error: Connection refused
[2024-04-08T15:11:30.327+0000] {thread.py:57} WARNING - [control connection] Error connecting to 172.21.0.4:9042:
Traceback (most recent call last):
  File "cassandra/cluster.py", line 3577, in cassandra.cluster.ControlConnection._reconnect_internal
  File "cassandra/cluster.py", line 3599, in cassandra.cluster.ControlConnection._try_connect
  File "cassandra/cluster.py", line 1670, in cassandra.cluster.Cluster.connection_factory
  File "cassandra/connection.py", line 846, in cassandra.connection.Connection.factory
  File "/home/airflow/.local/lib/python3.8/site-packages/cassandra/io/libevreactor.py", line 266, in __init__
    self._connect_socket()
  File "cassandra/connection.py", line 951, in cassandra.connection.Connection._connect_socket
ConnectionRefusedError: [Errno 111] Tried connecting to [('172.21.0.4', 9042)]. Last error: Connection refused
[2024-04-08T15:11:30.341+0000] {thread.py:57} WARNING - [control connection] Error connecting to 172.21.0.4:9042:
Traceback (most recent call last):
  File "cassandra/cluster.py", line 3577, in cassandra.cluster.ControlConnection._reconnect_internal
  File "cassandra/cluster.py", line 3599, in cassandra.cluster.ControlConnection._try_connect
  File "cassandra/cluster.py", line 1670, in cassandra.cluster.Cluster.connection_factory
  File "cassandra/connection.py", line 846, in cassandra.connection.Connection.factory
  File "/home/airflow/.local/lib/python3.8/site-packages/cassandra/io/libevreactor.py", line 266, in __init__
    self._connect_socket()
  File "cassandra/connection.py", line 951, in cassandra.connection.Connection._connect_socket
ConnectionRefusedError: [Errno 111] Tried connecting to [('172.21.0.4', 9042)]. Last error: Connection refused
[2024-04-08T15:11:30.434+0000] {thread.py:57} WARNING - [control connection] Error connecting to 172.21.0.4:9042:
Traceback (most recent call last):
  File "cassandra/cluster.py", line 3577, in cassandra.cluster.ControlConnection._reconnect_internal
  File "cassandra/cluster.py", line 3599, in cassandra.cluster.ControlConnection._try_connect
  File "cassandra/cluster.py", line 1670, in cassandra.cluster.Cluster.connection_factory
  File "cassandra/connection.py", line 846, in cassandra.connection.Connection.factory
  File "/home/airflow/.local/lib/python3.8/site-packages/cassandra/io/libevreactor.py", line 266, in __init__
    self._connect_socket()
  File "cassandra/connection.py", line 951, in cassandra.connection.Connection._connect_socket
ConnectionRefusedError: [Errno 111] Tried connecting to [('172.21.0.4', 9042)]. Last error: Connection refused
[2024-04-08T15:11:30.441+0000] {thread.py:57} WARNING - [control connection] Error connecting to 172.21.0.4:9042:
Traceback (most recent call last):
  File "cassandra/cluster.py", line 3577, in cassandra.cluster.ControlConnection._reconnect_internal
  File "cassandra/cluster.py", line 3599, in cassandra.cluster.ControlConnection._try_connect
  File "cassandra/cluster.py", line 1670, in cassandra.cluster.Cluster.connection_factory
  File "cassandra/connection.py", line 846, in cassandra.connection.Connection.factory
  File "/home/airflow/.local/lib/python3.8/site-packages/cassandra/io/libevreactor.py", line 266, in __init__
    self._connect_socket()
  File "cassandra/connection.py", line 951, in cassandra.connection.Connection._connect_socket
ConnectionRefusedError: [Errno 111] Tried connecting to [('172.21.0.4', 9042)]. Last error: Connection refused
[2024-04-08T15:11:30.686+0000] {taskinstance.py:2731} ERROR - Task failed with exception
Traceback (most recent call last):
  File "/home/airflow/.local/lib/python3.8/site-packages/airflow/models/taskinstance.py", line 444, in _execute_task
    result = _execute_callable(context=context, **execute_callable_kwargs)
  File "/home/airflow/.local/lib/python3.8/site-packages/airflow/models/taskinstance.py", line 414, in _execute_callable
    return execute_callable(context=context, **execute_callable_kwargs)
  File "/home/airflow/.local/lib/python3.8/site-packages/airflow/sensors/base.py", line 265, in execute
    raise e
  File "/home/airflow/.local/lib/python3.8/site-packages/airflow/sensors/base.py", line 247, in execute
    poke_return = self.poke(context)
  File "/home/airflow/.local/lib/python3.8/site-packages/airflow/providers/apache/cassandra/sensors/record.py", line 72, in poke
    hook = CassandraHook(self.cassandra_conn_id)
  File "/home/airflow/.local/lib/python3.8/site-packages/airflow/providers/apache/cassandra/hooks/cassandra.py", line 90, in __init__
    conn = self.get_connection(cassandra_conn_id)
  File "/home/airflow/.local/lib/python3.8/site-packages/airflow/hooks/base.py", line 82, in get_connection
    conn = Connection.get_connection_from_secrets(conn_id)
  File "/home/airflow/.local/lib/python3.8/site-packages/airflow/models/connection.py", line 514, in get_connection_from_secrets
    raise AirflowNotFoundException(f"The conn_id `{conn_id}` isn't defined")
airflow.exceptions.AirflowNotFoundException: The conn_id `cassandra_conn` isn't defined
[2024-04-08T15:11:30.868+0000] {taskinstance.py:1149} INFO - Marking task as UP_FOR_RETRY. dag_id=cassandra_sensor_dag, task_id=cassandra_sensor_record, execution_date=20240408T002500, start_date=20240408T150428, end_date=20240408T151130
[2024-04-08T15:11:30.966+0000] {standard_task_runner.py:107} ERROR - Failed to execute job 128 for task cassandra_sensor_record (The conn_id `cassandra_conn` isn't defined; 1575)
[2024-04-08T15:11:31.090+0000] {local_task_job_runner.py:234} INFO - Task exited with return code 1
[2024-04-08T15:11:31.261+0000] {taskinstance.py:3312} INFO - 0 downstream tasks scheduled from follow-on schedule check
