[2024-04-08T14:44:22.268+0000] {taskinstance.py:1979} INFO - Dependencies all met for dep_context=non-requeueable deps ti=<TaskInstance: cassandra_sensor_dag.cassandra_sensor manual__2024-04-08T14:40:51.735420+00:00 [queued]>
[2024-04-08T14:44:22.306+0000] {taskinstance.py:1979} INFO - Dependencies all met for dep_context=requeueable deps ti=<TaskInstance: cassandra_sensor_dag.cassandra_sensor manual__2024-04-08T14:40:51.735420+00:00 [queued]>
[2024-04-08T14:44:22.307+0000] {taskinstance.py:2193} INFO - Starting attempt 1 of 2
[2024-04-08T14:44:22.360+0000] {taskinstance.py:2217} INFO - Executing <Task(CassandraTableSensor): cassandra_sensor> on 2024-04-08 14:40:51.735420+00:00
[2024-04-08T14:44:22.382+0000] {standard_task_runner.py:60} INFO - Started process 319 to run task
[2024-04-08T14:44:22.396+0000] {standard_task_runner.py:87} INFO - Running: ['***', 'tasks', 'run', 'cassandra_sensor_dag', 'cassandra_sensor', 'manual__2024-04-08T14:40:51.735420+00:00', '--job-id', '47', '--raw', '--subdir', 'DAGS_FOLDER/test.py', '--cfg-path', '/tmp/tmpcnx5l8al']
[2024-04-08T14:44:22.405+0000] {standard_task_runner.py:88} INFO - Job 47: Subtask cassandra_sensor
[2024-04-08T14:44:22.629+0000] {task_command.py:423} INFO - Running <TaskInstance: cassandra_sensor_dag.cassandra_sensor manual__2024-04-08T14:40:51.735420+00:00 [running]> on host c2d2cc8ff432
[2024-04-08T14:44:23.079+0000] {taskinstance.py:2513} INFO - Exporting env vars: AIRFLOW_CTX_DAG_OWNER='***' AIRFLOW_CTX_DAG_ID='cassandra_sensor_dag' AIRFLOW_CTX_TASK_ID='cassandra_sensor' AIRFLOW_CTX_EXECUTION_DATE='2024-04-08T14:40:51.735420+00:00' AIRFLOW_CTX_TRY_NUMBER='1' AIRFLOW_CTX_DAG_RUN_ID='manual__2024-04-08T14:40:51.735420+00:00'
[2024-04-08T14:44:23.086+0000] {table.py:65} INFO - Sensor check existence of table: users
[2024-04-08T14:44:23.151+0000] {base.py:83} INFO - Using connection ID 'cassandra_conn' for task execution.
[2024-04-08T14:44:23.157+0000] {warnings.py:109} WARNING - /home/***/.local/lib/python3.8/site-packages/***/providers/apache/cassandra/hooks/cassandra.py:120: DeprecationWarning: Legacy execution parameters will be removed in 4.0. Consider using execution profiles.
  self.cluster = Cluster(**conn_config)

[2024-04-08T14:44:23.173+0000] {cassandra.py:128} WARNING - [control connection] Error connecting to 127.0.0.1:9042:
Traceback (most recent call last):
  File "cassandra/cluster.py", line 3577, in cassandra.cluster.ControlConnection._reconnect_internal
  File "cassandra/cluster.py", line 3599, in cassandra.cluster.ControlConnection._try_connect
  File "cassandra/cluster.py", line 1670, in cassandra.cluster.Cluster.connection_factory
  File "cassandra/connection.py", line 846, in cassandra.connection.Connection.factory
  File "/home/airflow/.local/lib/python3.8/site-packages/cassandra/io/libevreactor.py", line 266, in __init__
    self._connect_socket()
  File "cassandra/connection.py", line 951, in cassandra.connection.Connection._connect_socket
ConnectionRefusedError: [Errno 111] Tried connecting to [('127.0.0.1', 9042)]. Last error: Connection refused
[2024-04-08T14:44:23.187+0000] {cassandra.py:128} ERROR - Control connection failed to connect, shutting down Cluster:
Traceback (most recent call last):
  File "cassandra/cluster.py", line 1740, in cassandra.cluster.Cluster.connect
  File "cassandra/cluster.py", line 3543, in cassandra.cluster.ControlConnection.connect
  File "cassandra/cluster.py", line 3588, in cassandra.cluster.ControlConnection._reconnect_internal
cassandra.cluster.NoHostAvailable: ('Unable to connect to any servers', {'127.0.0.1:9042': ConnectionRefusedError(111, "Tried connecting to [('127.0.0.1', 9042)]. Last error: Connection refused")})
[2024-04-08T14:44:23.200+0000] {taskinstance.py:2731} ERROR - Task failed with exception
Traceback (most recent call last):
  File "/home/airflow/.local/lib/python3.8/site-packages/airflow/models/taskinstance.py", line 444, in _execute_task
    result = _execute_callable(context=context, **execute_callable_kwargs)
  File "/home/airflow/.local/lib/python3.8/site-packages/airflow/models/taskinstance.py", line 414, in _execute_callable
    return execute_callable(context=context, **execute_callable_kwargs)
  File "/home/airflow/.local/lib/python3.8/site-packages/airflow/sensors/base.py", line 265, in execute
    raise e
  File "/home/airflow/.local/lib/python3.8/site-packages/airflow/sensors/base.py", line 247, in execute
    poke_return = self.poke(context)
  File "/home/airflow/.local/lib/python3.8/site-packages/airflow/providers/apache/cassandra/sensors/table.py", line 67, in poke
    return hook.table_exists(self.table)
  File "/home/airflow/.local/lib/python3.8/site-packages/airflow/providers/apache/cassandra/hooks/cassandra.py", line 185, in table_exists
    cluster_metadata = self.get_conn().cluster.metadata
  File "/home/airflow/.local/lib/python3.8/site-packages/airflow/providers/apache/cassandra/hooks/cassandra.py", line 128, in get_conn
    self.session = self.cluster.connect(self.keyspace)
  File "cassandra/cluster.py", line 1717, in cassandra.cluster.Cluster.connect
  File "cassandra/cluster.py", line 1753, in cassandra.cluster.Cluster.connect
  File "cassandra/cluster.py", line 1740, in cassandra.cluster.Cluster.connect
  File "cassandra/cluster.py", line 3543, in cassandra.cluster.ControlConnection.connect
  File "cassandra/cluster.py", line 3588, in cassandra.cluster.ControlConnection._reconnect_internal
cassandra.cluster.NoHostAvailable: ('Unable to connect to any servers', {'127.0.0.1:9042': ConnectionRefusedError(111, "Tried connecting to [('127.0.0.1', 9042)]. Last error: Connection refused")})
[2024-04-08T14:44:23.251+0000] {taskinstance.py:1149} INFO - Marking task as UP_FOR_RETRY. dag_id=cassandra_sensor_dag, task_id=cassandra_sensor, execution_date=20240408T144051, start_date=20240408T144422, end_date=20240408T144423
[2024-04-08T14:44:23.617+0000] {standard_task_runner.py:107} ERROR - Failed to execute job 47 for task cassandra_sensor (('Unable to connect to any servers', {'127.0.0.1:9042': ConnectionRefusedError(111, "Tried connecting to [('127.0.0.1', 9042)]. Last error: Connection refused")}); 319)
[2024-04-08T14:44:23.655+0000] {local_task_job_runner.py:234} INFO - Task exited with return code 1
[2024-04-08T14:44:23.862+0000] {taskinstance.py:3312} INFO - 0 downstream tasks scheduled from follow-on schedule check
