[2024-04-08T14:53:29.566+0000] {taskinstance.py:1979} INFO - Dependencies all met for dep_context=non-requeueable deps ti=<TaskInstance: cassandra_sensor_dag.cassandra_sensor manual__2024-04-08T14:48:20.808241+00:00 [queued]>
[2024-04-08T14:53:29.591+0000] {taskinstance.py:1979} INFO - Dependencies all met for dep_context=requeueable deps ti=<TaskInstance: cassandra_sensor_dag.cassandra_sensor manual__2024-04-08T14:48:20.808241+00:00 [queued]>
[2024-04-08T14:53:29.592+0000] {taskinstance.py:2193} INFO - Starting attempt 2 of 2
[2024-04-08T14:53:29.639+0000] {taskinstance.py:2217} INFO - Executing <Task(CassandraTableSensor): cassandra_sensor> on 2024-04-08 14:48:20.808241+00:00
[2024-04-08T14:53:29.656+0000] {standard_task_runner.py:60} INFO - Started process 644 to run task
[2024-04-08T14:53:29.667+0000] {standard_task_runner.py:87} INFO - Running: ['***', 'tasks', 'run', 'cassandra_sensor_dag', 'cassandra_sensor', 'manual__2024-04-08T14:48:20.808241+00:00', '--job-id', '76', '--raw', '--subdir', 'DAGS_FOLDER/test.py', '--cfg-path', '/tmp/tmpu7qa7sj7']
[2024-04-08T14:53:29.677+0000] {standard_task_runner.py:88} INFO - Job 76: Subtask cassandra_sensor
[2024-04-08T14:53:30.116+0000] {task_command.py:423} INFO - Running <TaskInstance: cassandra_sensor_dag.cassandra_sensor manual__2024-04-08T14:48:20.808241+00:00 [running]> on host c2d2cc8ff432
[2024-04-08T14:53:30.449+0000] {taskinstance.py:2513} INFO - Exporting env vars: AIRFLOW_CTX_DAG_OWNER='***' AIRFLOW_CTX_DAG_ID='cassandra_sensor_dag' AIRFLOW_CTX_TASK_ID='cassandra_sensor' AIRFLOW_CTX_EXECUTION_DATE='2024-04-08T14:48:20.808241+00:00' AIRFLOW_CTX_TRY_NUMBER='2' AIRFLOW_CTX_DAG_RUN_ID='manual__2024-04-08T14:48:20.808241+00:00'
[2024-04-08T14:53:30.460+0000] {table.py:65} INFO - Sensor check existence of table: users
[2024-04-08T14:53:30.493+0000] {base.py:83} INFO - Using connection ID 'cassandra_conn' for task execution.
[2024-04-08T14:53:30.507+0000] {warnings.py:109} WARNING - /home/***/.local/lib/python3.8/site-packages/***/providers/apache/cassandra/hooks/cassandra.py:120: DeprecationWarning: Legacy execution parameters will be removed in 4.0. Consider using execution profiles.
  self.cluster = Cluster(**conn_config)

[2024-04-08T14:53:30.555+0000] {cassandra.py:128} WARNING - Downgrading core protocol version from 66 to 65 for 172.21.0.4:9042. To avoid this, it is best practice to explicitly set Cluster(protocol_version) to the version supported by your cluster. http://datastax.github.io/python-driver/api/cassandra/cluster.html#cassandra.cluster.Cluster.protocol_version
[2024-04-08T14:53:30.574+0000] {cassandra.py:128} WARNING - Downgrading core protocol version from 65 to 5 for 172.21.0.4:9042. To avoid this, it is best practice to explicitly set Cluster(protocol_version) to the version supported by your cluster. http://datastax.github.io/python-driver/api/cassandra/cluster.html#cassandra.cluster.Cluster.protocol_version
[2024-04-08T14:53:30.814+0000] {thread.py:57} WARNING - Failed to create connection pool for new host 172.21.0.4:9042:
Traceback (most recent call last):
  File "cassandra/connection.py", line 1503, in cassandra.connection.Connection.set_keyspace_blocking
  File "cassandra/connection.py", line 1082, in cassandra.connection.Connection.wait_for_response
  File "cassandra/connection.py", line 1129, in cassandra.connection.Connection.wait_for_responses
  File "cassandra/connection.py", line 1124, in cassandra.connection.Connection.wait_for_responses
  File "cassandra/connection.py", line 1634, in cassandra.connection.ResponseWaiter.deliver
cassandra.InvalidRequest: Error from server: code=2200 [Invalid query] message="Keyspace 'test_dna' does not exist"

During handling of the above exception, another exception occurred:

Traceback (most recent call last):
  File "cassandra/cluster.py", line 3234, in cassandra.cluster.Session.add_or_renew_pool.run_add_or_renew_pool
  File "cassandra/pool.py", line 409, in cassandra.pool.HostConnection.__init__
  File "cassandra/connection.py", line 1511, in cassandra.connection.Connection.set_keyspace_blocking
cassandra.connection.ConnectionException: Problem while setting keyspace: InvalidRequest('Error from server: code=2200 [Invalid query] message="Keyspace \'test_dna\' does not exist"')
[2024-04-08T14:53:30.820+0000] {thread.py:57} WARNING - Host 172.21.0.4:9042 has been marked down
[2024-04-08T14:53:30.825+0000] {taskinstance.py:2731} ERROR - Task failed with exception
Traceback (most recent call last):
  File "/home/airflow/.local/lib/python3.8/site-packages/airflow/models/taskinstance.py", line 444, in _execute_task
    result = _execute_callable(context=context, **execute_callable_kwargs)
  File "/home/airflow/.local/lib/python3.8/site-packages/airflow/models/taskinstance.py", line 414, in _execute_callable
    return execute_callable(context=context, **execute_callable_kwargs)
  File "/home/airflow/.local/lib/python3.8/site-packages/airflow/sensors/base.py", line 265, in execute
    raise e
  File "/home/airflow/.local/lib/python3.8/site-packages/airflow/sensors/base.py", line 247, in execute
    poke_return = self.poke(context)
  File "/home/airflow/.local/lib/python3.8/site-packages/airflow/providers/apache/cassandra/sensors/table.py", line 67, in poke
    return hook.table_exists(self.table)
  File "/home/airflow/.local/lib/python3.8/site-packages/airflow/providers/apache/cassandra/hooks/cassandra.py", line 185, in table_exists
    cluster_metadata = self.get_conn().cluster.metadata
  File "/home/airflow/.local/lib/python3.8/site-packages/airflow/providers/apache/cassandra/hooks/cassandra.py", line 128, in get_conn
    self.session = self.cluster.connect(self.keyspace)
  File "cassandra/cluster.py", line 1765, in cassandra.cluster.Cluster.connect
  File "cassandra/cluster.py", line 1822, in cassandra.cluster.Cluster._new_session
  File "cassandra/cluster.py", line 2603, in cassandra.cluster.Session.__init__
cassandra.cluster.NoHostAvailable: ("Unable to connect to any servers using keyspace 'test_dna'", ['172.21.0.4'])
[2024-04-08T14:53:30.864+0000] {taskinstance.py:1149} INFO - Marking task as FAILED. dag_id=cassandra_sensor_dag, task_id=cassandra_sensor, execution_date=20240408T144820, start_date=20240408T145329, end_date=20240408T145330
[2024-04-08T14:53:30.929+0000] {standard_task_runner.py:107} ERROR - Failed to execute job 76 for task cassandra_sensor (("Unable to connect to any servers using keyspace 'test_dna'", ['172.21.0.4']); 644)
[2024-04-08T14:53:30.976+0000] {local_task_job_runner.py:234} INFO - Task exited with return code 1
[2024-04-08T14:53:31.071+0000] {taskinstance.py:3312} INFO - 0 downstream tasks scheduled from follow-on schedule check
