[2024-04-08T14:57:57.469+0000] {taskinstance.py:1979} INFO - Dependencies all met for dep_context=non-requeueable deps ti=<TaskInstance: cassandra_sensor_dag.cassandra_sensor_record scheduled__2024-04-08T01:05:00+00:00 [queued]>
[2024-04-08T14:57:57.600+0000] {taskinstance.py:1979} INFO - Dependencies all met for dep_context=requeueable deps ti=<TaskInstance: cassandra_sensor_dag.cassandra_sensor_record scheduled__2024-04-08T01:05:00+00:00 [queued]>
[2024-04-08T14:57:57.620+0000] {taskinstance.py:2193} INFO - Starting attempt 1 of 2
[2024-04-08T14:57:58.027+0000] {taskinstance.py:2217} INFO - Executing <Task(CassandraRecordSensor): cassandra_sensor_record> on 2024-04-08 01:05:00+00:00
[2024-04-08T14:57:58.191+0000] {standard_task_runner.py:60} INFO - Started process 1036 to run task
[2024-04-08T14:57:58.398+0000] {standard_task_runner.py:87} INFO - Running: ['***', 'tasks', 'run', 'cassandra_sensor_dag', 'cassandra_sensor_record', 'scheduled__2024-04-08T01:05:00+00:00', '--job-id', '98', '--raw', '--subdir', 'DAGS_FOLDER/test.py', '--cfg-path', '/tmp/tmpml3g_v1a']
[2024-04-08T14:57:58.451+0000] {standard_task_runner.py:88} INFO - Job 98: Subtask cassandra_sensor_record
[2024-04-08T14:58:01.029+0000] {task_command.py:423} INFO - Running <TaskInstance: cassandra_sensor_dag.cassandra_sensor_record scheduled__2024-04-08T01:05:00+00:00 [running]> on host c2d2cc8ff432
[2024-04-08T14:58:04.371+0000] {taskinstance.py:2513} INFO - Exporting env vars: AIRFLOW_CTX_DAG_OWNER='***' AIRFLOW_CTX_DAG_ID='cassandra_sensor_dag' AIRFLOW_CTX_TASK_ID='cassandra_sensor_record' AIRFLOW_CTX_EXECUTION_DATE='2024-04-08T01:05:00+00:00' AIRFLOW_CTX_TRY_NUMBER='1' AIRFLOW_CTX_DAG_RUN_ID='scheduled__2024-04-08T01:05:00+00:00'
[2024-04-08T14:58:04.408+0000] {record.py:71} INFO - Sensor check existence of record: ['user_id', 'age', 'email', 'name']
[2024-04-08T14:58:04.557+0000] {base.py:83} INFO - Using connection ID 'cassandra_conn' for task execution.
[2024-04-08T14:58:04.618+0000] {warnings.py:109} WARNING - /home/***/.local/lib/python3.8/site-packages/***/providers/apache/cassandra/hooks/cassandra.py:120: DeprecationWarning: Legacy execution parameters will be removed in 4.0. Consider using execution profiles.
  self.cluster = Cluster(**conn_config)

[2024-04-08T14:58:04.750+0000] {cassandra.py:128} WARNING - Downgrading core protocol version from 66 to 65 for 172.21.0.4:9042. To avoid this, it is best practice to explicitly set Cluster(protocol_version) to the version supported by your cluster. http://datastax.github.io/python-driver/api/cassandra/cluster.html#cassandra.cluster.Cluster.protocol_version
[2024-04-08T14:58:04.810+0000] {cassandra.py:128} WARNING - Downgrading core protocol version from 65 to 5 for 172.21.0.4:9042. To avoid this, it is best practice to explicitly set Cluster(protocol_version) to the version supported by your cluster. http://datastax.github.io/python-driver/api/cassandra/cluster.html#cassandra.cluster.Cluster.protocol_version
[2024-04-08T14:58:06.900+0000] {cassandra.py:128} WARNING - [control connection] Error connecting to 172.21.0.4:9042:
Traceback (most recent call last):
  File "cassandra/cluster.py", line 3577, in cassandra.cluster.ControlConnection._reconnect_internal
  File "cassandra/cluster.py", line 3654, in cassandra.cluster.ControlConnection._try_connect
  File "cassandra/cluster.py", line 3635, in cassandra.cluster.ControlConnection._try_connect
  File "cassandra/connection.py", line 1126, in cassandra.connection.Connection.wait_for_responses
  File "cassandra/connection.py", line 1124, in cassandra.connection.Connection.wait_for_responses
  File "cassandra/connection.py", line 1636, in cassandra.connection.ResponseWaiter.deliver
cassandra.OperationTimedOut: errors=None, last_host=None
[2024-04-08T14:58:06.907+0000] {cassandra.py:128} ERROR - Control connection failed to connect, shutting down Cluster:
Traceback (most recent call last):
  File "cassandra/cluster.py", line 1740, in cassandra.cluster.Cluster.connect
  File "cassandra/cluster.py", line 3543, in cassandra.cluster.ControlConnection.connect
  File "cassandra/cluster.py", line 3588, in cassandra.cluster.ControlConnection._reconnect_internal
cassandra.cluster.NoHostAvailable: ('Unable to connect to any servers', {'172.21.0.4:9042': OperationTimedOut('errors=None, last_host=None')})
[2024-04-08T14:59:07.013+0000] {record.py:71} INFO - Sensor check existence of record: ['user_id', 'age', 'email', 'name']
[2024-04-08T14:59:07.123+0000] {base.py:83} INFO - Using connection ID 'cassandra_conn' for task execution.
[2024-04-08T14:59:07.175+0000] {cassandra.py:128} WARNING - Downgrading core protocol version from 66 to 65 for 172.21.0.4:9042. To avoid this, it is best practice to explicitly set Cluster(protocol_version) to the version supported by your cluster. http://datastax.github.io/python-driver/api/cassandra/cluster.html#cassandra.cluster.Cluster.protocol_version
[2024-04-08T14:59:07.180+0000] {cassandra.py:128} WARNING - Downgrading core protocol version from 65 to 5 for 172.21.0.4:9042. To avoid this, it is best practice to explicitly set Cluster(protocol_version) to the version supported by your cluster. http://datastax.github.io/python-driver/api/cassandra/cluster.html#cassandra.cluster.Cluster.protocol_version
[2024-04-08T15:00:07.723+0000] {record.py:71} INFO - Sensor check existence of record: ['user_id', 'age', 'email', 'name']
[2024-04-08T15:00:08.175+0000] {base.py:83} INFO - Using connection ID 'cassandra_conn' for task execution.
[2024-04-08T15:00:08.363+0000] {cassandra.py:128} WARNING - Downgrading core protocol version from 66 to 65 for 172.21.0.4:9042. To avoid this, it is best practice to explicitly set Cluster(protocol_version) to the version supported by your cluster. http://datastax.github.io/python-driver/api/cassandra/cluster.html#cassandra.cluster.Cluster.protocol_version
[2024-04-08T15:00:08.507+0000] {cassandra.py:128} WARNING - Downgrading core protocol version from 65 to 5 for 172.21.0.4:9042. To avoid this, it is best practice to explicitly set Cluster(protocol_version) to the version supported by your cluster. http://datastax.github.io/python-driver/api/cassandra/cluster.html#cassandra.cluster.Cluster.protocol_version
[2024-04-08T15:01:09.767+0000] {record.py:71} INFO - Sensor check existence of record: ['user_id', 'age', 'email', 'name']
[2024-04-08T15:01:09.912+0000] {base.py:83} INFO - Using connection ID 'cassandra_conn' for task execution.
[2024-04-08T15:01:10.014+0000] {cassandra.py:128} WARNING - Downgrading core protocol version from 66 to 65 for 172.21.0.4:9042. To avoid this, it is best practice to explicitly set Cluster(protocol_version) to the version supported by your cluster. http://datastax.github.io/python-driver/api/cassandra/cluster.html#cassandra.cluster.Cluster.protocol_version
[2024-04-08T15:01:10.074+0000] {cassandra.py:128} WARNING - Downgrading core protocol version from 65 to 5 for 172.21.0.4:9042. To avoid this, it is best practice to explicitly set Cluster(protocol_version) to the version supported by your cluster. http://datastax.github.io/python-driver/api/cassandra/cluster.html#cassandra.cluster.Cluster.protocol_version
[2024-04-08T15:02:11.440+0000] {record.py:71} INFO - Sensor check existence of record: ['user_id', 'age', 'email', 'name']
[2024-04-08T15:02:11.601+0000] {base.py:83} INFO - Using connection ID 'cassandra_conn' for task execution.
[2024-04-08T15:02:11.708+0000] {cassandra.py:128} WARNING - Downgrading core protocol version from 66 to 65 for 172.21.0.4:9042. To avoid this, it is best practice to explicitly set Cluster(protocol_version) to the version supported by your cluster. http://datastax.github.io/python-driver/api/cassandra/cluster.html#cassandra.cluster.Cluster.protocol_version
[2024-04-08T15:02:11.752+0000] {cassandra.py:128} WARNING - Downgrading core protocol version from 65 to 5 for 172.21.0.4:9042. To avoid this, it is best practice to explicitly set Cluster(protocol_version) to the version supported by your cluster. http://datastax.github.io/python-driver/api/cassandra/cluster.html#cassandra.cluster.Cluster.protocol_version
[2024-04-08T15:02:50.657+0000] {local_task_job_runner.py:302} WARNING - State of this instance has been externally set to None. Terminating instance.
[2024-04-08T15:02:50.688+0000] {process_utils.py:131} INFO - Sending 15 to group 1036. PIDs of all processes in the group: [1036]
[2024-04-08T15:02:50.701+0000] {process_utils.py:86} INFO - Sending the signal 15 to group 1036
[2024-04-08T15:02:50.710+0000] {taskinstance.py:2483} ERROR - Received SIGTERM. Terminating subprocesses.
[2024-04-08T15:02:50.797+0000] {taskinstance.py:2731} ERROR - Task failed with exception
Traceback (most recent call last):
  File "/home/airflow/.local/lib/python3.8/site-packages/airflow/models/taskinstance.py", line 444, in _execute_task
    result = _execute_callable(context=context, **execute_callable_kwargs)
  File "/home/airflow/.local/lib/python3.8/site-packages/airflow/models/taskinstance.py", line 414, in _execute_callable
    return execute_callable(context=context, **execute_callable_kwargs)
  File "/home/airflow/.local/lib/python3.8/site-packages/airflow/sensors/base.py", line 293, in execute
    time.sleep(self._get_next_poke_interval(started_at, run_duration, try_number))
  File "/home/airflow/.local/lib/python3.8/site-packages/airflow/models/taskinstance.py", line 2485, in signal_handler
    raise AirflowException("Task received SIGTERM signal")
airflow.exceptions.AirflowException: Task received SIGTERM signal
[2024-04-08T15:02:50.821+0000] {taskinstance.py:1149} INFO - Marking task as FAILED. dag_id=cassandra_sensor_dag, task_id=cassandra_sensor_record, execution_date=20240408T010500, start_date=20240408T145757, end_date=20240408T150250
[2024-04-08T15:02:50.958+0000] {standard_task_runner.py:107} ERROR - Failed to execute job 98 for task cassandra_sensor_record ((psycopg2.errors.ForeignKeyViolation) insert or update on table "task_fail" violates foreign key constraint "task_fail_ti_fkey"
DETAIL:  Key (dag_id, task_id, run_id, map_index)=(cassandra_sensor_dag, cassandra_sensor_record, scheduled__2024-04-08T01:05:00+00:00, -1) is not present in table "task_instance".

[SQL: INSERT INTO task_fail (task_id, dag_id, run_id, map_index, start_date, end_date, duration) VALUES (%(task_id)s, %(dag_id)s, %(run_id)s, %(map_index)s, %(start_date)s, %(end_date)s, %(duration)s) RETURNING task_fail.id]
[parameters: {'task_id': 'cassandra_sensor_record', 'dag_id': 'cassandra_sensor_dag', 'run_id': 'scheduled__2024-04-08T01:05:00+00:00', 'map_index': -1, 'start_date': datetime.datetime(2024, 4, 8, 14, 57, 57, 483175, tzinfo=Timezone('UTC')), 'end_date': datetime.datetime(2024, 4, 8, 15, 2, 50, 817508, tzinfo=Timezone('UTC')), 'duration': 293}]
(Background on this error at: https://sqlalche.me/e/14/gkpj); 1036)
[2024-04-08T15:02:51.071+0000] {process_utils.py:79} INFO - Process psutil.Process(pid=1036, status='terminated', exitcode=1, started='14:57:57') (1036) terminated with exit code 1
[2024-04-08T15:04:50.318+0000] {taskinstance.py:1979} INFO - Dependencies all met for dep_context=non-requeueable deps ti=<TaskInstance: cassandra_sensor_dag.cassandra_sensor_record scheduled__2024-04-08T01:05:00+00:00 [queued]>
[2024-04-08T15:04:50.498+0000] {taskinstance.py:1979} INFO - Dependencies all met for dep_context=requeueable deps ti=<TaskInstance: cassandra_sensor_dag.cassandra_sensor_record scheduled__2024-04-08T01:05:00+00:00 [queued]>
[2024-04-08T15:04:50.509+0000] {taskinstance.py:2193} INFO - Starting attempt 1 of 2
[2024-04-08T15:04:51.141+0000] {taskinstance.py:2217} INFO - Executing <Task(CassandraRecordSensor): cassandra_sensor_record> on 2024-04-08 01:05:00+00:00
[2024-04-08T15:04:51.189+0000] {standard_task_runner.py:60} INFO - Started process 1630 to run task
[2024-04-08T15:04:51.228+0000] {standard_task_runner.py:87} INFO - Running: ['***', 'tasks', 'run', 'cassandra_sensor_dag', 'cassandra_sensor_record', 'scheduled__2024-04-08T01:05:00+00:00', '--job-id', '135', '--raw', '--subdir', 'DAGS_FOLDER/test.py', '--cfg-path', '/tmp/tmpdfxx2x67']
[2024-04-08T15:04:51.273+0000] {standard_task_runner.py:88} INFO - Job 135: Subtask cassandra_sensor_record
[2024-04-08T15:04:52.268+0000] {task_command.py:423} INFO - Running <TaskInstance: cassandra_sensor_dag.cassandra_sensor_record scheduled__2024-04-08T01:05:00+00:00 [running]> on host c2d2cc8ff432
[2024-04-08T15:04:52.910+0000] {taskinstance.py:2513} INFO - Exporting env vars: AIRFLOW_CTX_DAG_OWNER='***' AIRFLOW_CTX_DAG_ID='cassandra_sensor_dag' AIRFLOW_CTX_TASK_ID='cassandra_sensor_record' AIRFLOW_CTX_EXECUTION_DATE='2024-04-08T01:05:00+00:00' AIRFLOW_CTX_TRY_NUMBER='1' AIRFLOW_CTX_DAG_RUN_ID='scheduled__2024-04-08T01:05:00+00:00'
[2024-04-08T15:04:52.934+0000] {record.py:71} INFO - Sensor check existence of record: ['user_id', 'age', 'email', 'name']
[2024-04-08T15:04:52.996+0000] {base.py:83} INFO - Using connection ID 'cassandra_conn' for task execution.
[2024-04-08T15:04:53.009+0000] {warnings.py:109} WARNING - /home/***/.local/lib/python3.8/site-packages/***/providers/apache/cassandra/hooks/cassandra.py:120: DeprecationWarning: Legacy execution parameters will be removed in 4.0. Consider using execution profiles.
  self.cluster = Cluster(**conn_config)

[2024-04-08T15:04:53.038+0000] {cassandra.py:128} WARNING - Downgrading core protocol version from 66 to 65 for 172.21.0.4:9042. To avoid this, it is best practice to explicitly set Cluster(protocol_version) to the version supported by your cluster. http://datastax.github.io/python-driver/api/cassandra/cluster.html#cassandra.cluster.Cluster.protocol_version
[2024-04-08T15:04:53.056+0000] {cassandra.py:128} WARNING - Downgrading core protocol version from 65 to 5 for 172.21.0.4:9042. To avoid this, it is best practice to explicitly set Cluster(protocol_version) to the version supported by your cluster. http://datastax.github.io/python-driver/api/cassandra/cluster.html#cassandra.cluster.Cluster.protocol_version
[2024-04-08T15:05:53.428+0000] {record.py:71} INFO - Sensor check existence of record: ['user_id', 'age', 'email', 'name']
[2024-04-08T15:05:53.568+0000] {base.py:83} INFO - Using connection ID 'cassandra_conn' for task execution.
[2024-04-08T15:05:53.619+0000] {cassandra.py:128} WARNING - Downgrading core protocol version from 66 to 65 for 172.21.0.4:9042. To avoid this, it is best practice to explicitly set Cluster(protocol_version) to the version supported by your cluster. http://datastax.github.io/python-driver/api/cassandra/cluster.html#cassandra.cluster.Cluster.protocol_version
[2024-04-08T15:05:53.635+0000] {cassandra.py:128} WARNING - Downgrading core protocol version from 65 to 5 for 172.21.0.4:9042. To avoid this, it is best practice to explicitly set Cluster(protocol_version) to the version supported by your cluster. http://datastax.github.io/python-driver/api/cassandra/cluster.html#cassandra.cluster.Cluster.protocol_version
[2024-04-08T15:06:53.956+0000] {record.py:71} INFO - Sensor check existence of record: ['user_id', 'age', 'email', 'name']
[2024-04-08T15:06:53.972+0000] {base.py:83} INFO - Using connection ID 'cassandra_conn' for task execution.
[2024-04-08T15:06:53.987+0000] {cassandra.py:128} WARNING - Downgrading core protocol version from 66 to 65 for 172.21.0.4:9042. To avoid this, it is best practice to explicitly set Cluster(protocol_version) to the version supported by your cluster. http://datastax.github.io/python-driver/api/cassandra/cluster.html#cassandra.cluster.Cluster.protocol_version
[2024-04-08T15:06:53.995+0000] {cassandra.py:128} WARNING - Downgrading core protocol version from 65 to 5 for 172.21.0.4:9042. To avoid this, it is best practice to explicitly set Cluster(protocol_version) to the version supported by your cluster. http://datastax.github.io/python-driver/api/cassandra/cluster.html#cassandra.cluster.Cluster.protocol_version
[2024-04-08T15:07:54.177+0000] {record.py:71} INFO - Sensor check existence of record: ['user_id', 'age', 'email', 'name']
[2024-04-08T15:07:54.326+0000] {base.py:83} INFO - Using connection ID 'cassandra_conn' for task execution.
[2024-04-08T15:07:54.408+0000] {cassandra.py:128} WARNING - Downgrading core protocol version from 66 to 65 for 172.21.0.4:9042. To avoid this, it is best practice to explicitly set Cluster(protocol_version) to the version supported by your cluster. http://datastax.github.io/python-driver/api/cassandra/cluster.html#cassandra.cluster.Cluster.protocol_version
[2024-04-08T15:07:54.669+0000] {cassandra.py:128} WARNING - Downgrading core protocol version from 65 to 5 for 172.21.0.4:9042. To avoid this, it is best practice to explicitly set Cluster(protocol_version) to the version supported by your cluster. http://datastax.github.io/python-driver/api/cassandra/cluster.html#cassandra.cluster.Cluster.protocol_version
[2024-04-08T15:08:56.177+0000] {record.py:71} INFO - Sensor check existence of record: ['user_id', 'age', 'email', 'name']
[2024-04-08T15:08:56.189+0000] {base.py:83} INFO - Using connection ID 'cassandra_conn' for task execution.
[2024-04-08T15:08:56.194+0000] {cassandra.py:128} WARNING - Downgrading core protocol version from 66 to 65 for 172.21.0.4:9042. To avoid this, it is best practice to explicitly set Cluster(protocol_version) to the version supported by your cluster. http://datastax.github.io/python-driver/api/cassandra/cluster.html#cassandra.cluster.Cluster.protocol_version
[2024-04-08T15:08:56.198+0000] {cassandra.py:128} WARNING - Downgrading core protocol version from 65 to 5 for 172.21.0.4:9042. To avoid this, it is best practice to explicitly set Cluster(protocol_version) to the version supported by your cluster. http://datastax.github.io/python-driver/api/cassandra/cluster.html#cassandra.cluster.Cluster.protocol_version
[2024-04-08T15:09:35.020+0000] {job.py:213} ERROR - Job heartbeat got an exception
Traceback (most recent call last):
  File "/home/airflow/.local/lib/python3.8/site-packages/sqlalchemy/engine/base.py", line 3371, in _wrap_pool_connect
    return fn()
  File "/home/airflow/.local/lib/python3.8/site-packages/sqlalchemy/pool/base.py", line 327, in connect
    return _ConnectionFairy._checkout(self)
  File "/home/airflow/.local/lib/python3.8/site-packages/sqlalchemy/pool/base.py", line 894, in _checkout
    fairy = _ConnectionRecord.checkout(pool)
  File "/home/airflow/.local/lib/python3.8/site-packages/sqlalchemy/pool/base.py", line 493, in checkout
    rec = pool._do_get()
  File "/home/airflow/.local/lib/python3.8/site-packages/sqlalchemy/pool/impl.py", line 256, in _do_get
    return self._create_connection()
  File "/home/airflow/.local/lib/python3.8/site-packages/sqlalchemy/pool/base.py", line 273, in _create_connection
    return _ConnectionRecord(self)
  File "/home/airflow/.local/lib/python3.8/site-packages/sqlalchemy/pool/base.py", line 388, in __init__
    self.__connect()
  File "/home/airflow/.local/lib/python3.8/site-packages/sqlalchemy/pool/base.py", line 691, in __connect
    pool.logger.debug("Error on connect(): %s", e)
  File "/home/airflow/.local/lib/python3.8/site-packages/sqlalchemy/util/langhelpers.py", line 70, in __exit__
    compat.raise_(
  File "/home/airflow/.local/lib/python3.8/site-packages/sqlalchemy/util/compat.py", line 211, in raise_
    raise exception
  File "/home/airflow/.local/lib/python3.8/site-packages/sqlalchemy/pool/base.py", line 686, in __connect
    self.dbapi_connection = connection = pool._invoke_creator(self)
  File "/home/airflow/.local/lib/python3.8/site-packages/sqlalchemy/engine/create.py", line 574, in connect
    return dialect.connect(*cargs, **cparams)
  File "/home/airflow/.local/lib/python3.8/site-packages/sqlalchemy/engine/default.py", line 598, in connect
    return self.dbapi.connect(*cargs, **cparams)
  File "/home/airflow/.local/lib/python3.8/site-packages/psycopg2/__init__.py", line 122, in connect
    conn = _connect(dsn, connection_factory=connection_factory, **kwasync)
psycopg2.OperationalError: could not translate host name "postgres" to address: Temporary failure in name resolution


The above exception was the direct cause of the following exception:

Traceback (most recent call last):
  File "/home/airflow/.local/lib/python3.8/site-packages/airflow/jobs/job.py", line 187, in heartbeat
    self._merge_from(Job._fetch_from_db(self, session))
  File "/home/airflow/.local/lib/python3.8/site-packages/airflow/api_internal/internal_api_call.py", line 114, in wrapper
    return func(*args, **kwargs)
  File "/home/airflow/.local/lib/python3.8/site-packages/airflow/utils/session.py", line 76, in wrapper
    return func(*args, **kwargs)
  File "/home/airflow/.local/lib/python3.8/site-packages/airflow/jobs/job.py", line 310, in _fetch_from_db
    session.merge(job)
  File "/home/airflow/.local/lib/python3.8/site-packages/sqlalchemy/orm/session.py", line 3056, in merge
    return self._merge(
  File "/home/airflow/.local/lib/python3.8/site-packages/sqlalchemy/orm/session.py", line 3136, in _merge
    merged = self.get(
  File "/home/airflow/.local/lib/python3.8/site-packages/sqlalchemy/orm/session.py", line 2853, in get
    return self._get_impl(
  File "/home/airflow/.local/lib/python3.8/site-packages/sqlalchemy/orm/session.py", line 2975, in _get_impl
    return db_load_fn(
  File "/home/airflow/.local/lib/python3.8/site-packages/sqlalchemy/orm/loading.py", line 530, in load_on_pk_identity
    session.execute(
  File "/home/airflow/.local/lib/python3.8/site-packages/sqlalchemy/orm/session.py", line 1716, in execute
    conn = self._connection_for_bind(bind)
  File "/home/airflow/.local/lib/python3.8/site-packages/sqlalchemy/orm/session.py", line 1555, in _connection_for_bind
    return self._transaction._connection_for_bind(
  File "/home/airflow/.local/lib/python3.8/site-packages/sqlalchemy/orm/session.py", line 750, in _connection_for_bind
    conn = bind.connect()
  File "/home/airflow/.local/lib/python3.8/site-packages/sqlalchemy/future/engine.py", line 412, in connect
    return super(Engine, self).connect()
  File "/home/airflow/.local/lib/python3.8/site-packages/sqlalchemy/engine/base.py", line 3325, in connect
    return self._connection_cls(self, close_with_result=close_with_result)
  File "/home/airflow/.local/lib/python3.8/site-packages/sqlalchemy/engine/base.py", line 96, in __init__
    else engine.raw_connection()
  File "/home/airflow/.local/lib/python3.8/site-packages/sqlalchemy/engine/base.py", line 3404, in raw_connection
    return self._wrap_pool_connect(self.pool.connect, _connection)
  File "/home/airflow/.local/lib/python3.8/site-packages/sqlalchemy/engine/base.py", line 3374, in _wrap_pool_connect
    Connection._handle_dbapi_exception_noconnection(
  File "/home/airflow/.local/lib/python3.8/site-packages/sqlalchemy/engine/base.py", line 2208, in _handle_dbapi_exception_noconnection
    util.raise_(
  File "/home/airflow/.local/lib/python3.8/site-packages/sqlalchemy/util/compat.py", line 211, in raise_
    raise exception
  File "/home/airflow/.local/lib/python3.8/site-packages/sqlalchemy/engine/base.py", line 3371, in _wrap_pool_connect
    return fn()
  File "/home/airflow/.local/lib/python3.8/site-packages/sqlalchemy/pool/base.py", line 327, in connect
    return _ConnectionFairy._checkout(self)
  File "/home/airflow/.local/lib/python3.8/site-packages/sqlalchemy/pool/base.py", line 894, in _checkout
    fairy = _ConnectionRecord.checkout(pool)
  File "/home/airflow/.local/lib/python3.8/site-packages/sqlalchemy/pool/base.py", line 493, in checkout
    rec = pool._do_get()
  File "/home/airflow/.local/lib/python3.8/site-packages/sqlalchemy/pool/impl.py", line 256, in _do_get
    return self._create_connection()
  File "/home/airflow/.local/lib/python3.8/site-packages/sqlalchemy/pool/base.py", line 273, in _create_connection
    return _ConnectionRecord(self)
  File "/home/airflow/.local/lib/python3.8/site-packages/sqlalchemy/pool/base.py", line 388, in __init__
    self.__connect()
  File "/home/airflow/.local/lib/python3.8/site-packages/sqlalchemy/pool/base.py", line 691, in __connect
    pool.logger.debug("Error on connect(): %s", e)
  File "/home/airflow/.local/lib/python3.8/site-packages/sqlalchemy/util/langhelpers.py", line 70, in __exit__
    compat.raise_(
  File "/home/airflow/.local/lib/python3.8/site-packages/sqlalchemy/util/compat.py", line 211, in raise_
    raise exception
  File "/home/airflow/.local/lib/python3.8/site-packages/sqlalchemy/pool/base.py", line 686, in __connect
    self.dbapi_connection = connection = pool._invoke_creator(self)
  File "/home/airflow/.local/lib/python3.8/site-packages/sqlalchemy/engine/create.py", line 574, in connect
    return dialect.connect(*cargs, **cparams)
  File "/home/airflow/.local/lib/python3.8/site-packages/sqlalchemy/engine/default.py", line 598, in connect
    return self.dbapi.connect(*cargs, **cparams)
  File "/home/airflow/.local/lib/python3.8/site-packages/psycopg2/__init__.py", line 122, in connect
    conn = _connect(dsn, connection_factory=connection_factory, **kwasync)
sqlalchemy.exc.OperationalError: (psycopg2.OperationalError) could not translate host name "postgres" to address: Temporary failure in name resolution

(Background on this error at: https://sqlalche.me/e/14/e3q8)
[2024-04-08T15:11:28.626+0000] {record.py:71} INFO - Sensor check existence of record: ['user_id', 'age', 'email', 'name']
[2024-04-08T15:11:28.884+0000] {job.py:221} ERROR - Job heartbeat failed with error. Scheduler is in unhealthy state
[2024-04-08T15:11:28.906+0000] {threading.py:932} WARNING - Heartbeat failed for connection (140560710160544) to 172.21.0.4:9042
[2024-04-08T15:11:28.914+0000] {threading.py:932} WARNING - Heartbeat failed for connection (140560709970768) to 172.21.0.4:9042
[2024-04-08T15:11:28.925+0000] {threading.py:932} WARNING - Failed sending heartbeat message on connection (140560710764192) to 172.21.0.4:9042
[2024-04-08T15:11:28.958+0000] {thread.py:57} WARNING - [control connection] Error connecting to 172.21.0.4:9042:
Traceback (most recent call last):
  File "cassandra/cluster.py", line 3577, in cassandra.cluster.ControlConnection._reconnect_internal
  File "cassandra/cluster.py", line 3599, in cassandra.cluster.ControlConnection._try_connect
  File "cassandra/cluster.py", line 1670, in cassandra.cluster.Cluster.connection_factory
  File "cassandra/connection.py", line 846, in cassandra.connection.Connection.factory
  File "/home/airflow/.local/lib/python3.8/site-packages/cassandra/io/libevreactor.py", line 266, in __init__
    self._connect_socket()
  File "cassandra/connection.py", line 951, in cassandra.connection.Connection._connect_socket
ConnectionRefusedError: [Errno 111] Tried connecting to [('172.21.0.4', 9042)]. Last error: Connection refused
[2024-04-08T15:11:28.946+0000] {thread.py:57} WARNING - [control connection] Error connecting to 172.21.0.4:9042:
Traceback (most recent call last):
  File "cassandra/cluster.py", line 3577, in cassandra.cluster.ControlConnection._reconnect_internal
  File "cassandra/cluster.py", line 3599, in cassandra.cluster.ControlConnection._try_connect
  File "cassandra/cluster.py", line 1670, in cassandra.cluster.Cluster.connection_factory
  File "cassandra/connection.py", line 846, in cassandra.connection.Connection.factory
  File "/home/airflow/.local/lib/python3.8/site-packages/cassandra/io/libevreactor.py", line 266, in __init__
    self._connect_socket()
  File "cassandra/connection.py", line 951, in cassandra.connection.Connection._connect_socket
ConnectionRefusedError: [Errno 111] Tried connecting to [('172.21.0.4', 9042)]. Last error: Connection refused
[2024-04-08T15:11:28.949+0000] {thread.py:57} WARNING - [control connection] Error connecting to 172.21.0.4:9042:
Traceback (most recent call last):
  File "cassandra/cluster.py", line 3577, in cassandra.cluster.ControlConnection._reconnect_internal
  File "cassandra/cluster.py", line 3599, in cassandra.cluster.ControlConnection._try_connect
  File "cassandra/cluster.py", line 1670, in cassandra.cluster.Cluster.connection_factory
  File "cassandra/connection.py", line 846, in cassandra.connection.Connection.factory
  File "/home/airflow/.local/lib/python3.8/site-packages/cassandra/io/libevreactor.py", line 266, in __init__
    self._connect_socket()
  File "cassandra/connection.py", line 951, in cassandra.connection.Connection._connect_socket
ConnectionRefusedError: [Errno 111] Tried connecting to [('172.21.0.4', 9042)]. Last error: Connection refused
[2024-04-08T15:11:28.955+0000] {thread.py:57} WARNING - [control connection] Error connecting to 172.21.0.4:9042:
Traceback (most recent call last):
  File "cassandra/cluster.py", line 3577, in cassandra.cluster.ControlConnection._reconnect_internal
  File "cassandra/cluster.py", line 3599, in cassandra.cluster.ControlConnection._try_connect
  File "cassandra/cluster.py", line 1670, in cassandra.cluster.Cluster.connection_factory
  File "cassandra/connection.py", line 846, in cassandra.connection.Connection.factory
  File "/home/airflow/.local/lib/python3.8/site-packages/cassandra/io/libevreactor.py", line 266, in __init__
    self._connect_socket()
  File "cassandra/connection.py", line 951, in cassandra.connection.Connection._connect_socket
ConnectionRefusedError: [Errno 111] Tried connecting to [('172.21.0.4', 9042)]. Last error: Connection refused
[2024-04-08T15:11:28.934+0000] {threading.py:932} WARNING - Heartbeat failed for connection (140560675146288) to 172.21.0.4:9042
[2024-04-08T15:11:29.096+0000] {thread.py:57} WARNING - [control connection] Error connecting to 172.21.0.4:9042:
Traceback (most recent call last):
  File "cassandra/cluster.py", line 3577, in cassandra.cluster.ControlConnection._reconnect_internal
  File "cassandra/cluster.py", line 3599, in cassandra.cluster.ControlConnection._try_connect
  File "cassandra/cluster.py", line 1670, in cassandra.cluster.Cluster.connection_factory
  File "cassandra/connection.py", line 846, in cassandra.connection.Connection.factory
  File "/home/airflow/.local/lib/python3.8/site-packages/cassandra/io/libevreactor.py", line 266, in __init__
    self._connect_socket()
  File "cassandra/connection.py", line 951, in cassandra.connection.Connection._connect_socket
ConnectionRefusedError: [Errno 111] Tried connecting to [('172.21.0.4', 9042)]. Last error: Connection refused
[2024-04-08T15:11:30.129+0000] {thread.py:57} WARNING - [control connection] Error connecting to 172.21.0.4:9042:
Traceback (most recent call last):
  File "cassandra/cluster.py", line 3577, in cassandra.cluster.ControlConnection._reconnect_internal
  File "cassandra/cluster.py", line 3599, in cassandra.cluster.ControlConnection._try_connect
  File "cassandra/cluster.py", line 1670, in cassandra.cluster.Cluster.connection_factory
  File "cassandra/connection.py", line 846, in cassandra.connection.Connection.factory
  File "/home/airflow/.local/lib/python3.8/site-packages/cassandra/io/libevreactor.py", line 266, in __init__
    self._connect_socket()
  File "cassandra/connection.py", line 951, in cassandra.connection.Connection._connect_socket
ConnectionRefusedError: [Errno 111] Tried connecting to [('172.21.0.4', 9042)]. Last error: Connection refused
[2024-04-08T15:11:30.140+0000] {thread.py:57} WARNING - [control connection] Error connecting to 172.21.0.4:9042:
Traceback (most recent call last):
  File "cassandra/cluster.py", line 3577, in cassandra.cluster.ControlConnection._reconnect_internal
  File "cassandra/cluster.py", line 3599, in cassandra.cluster.ControlConnection._try_connect
  File "cassandra/cluster.py", line 1670, in cassandra.cluster.Cluster.connection_factory
  File "cassandra/connection.py", line 846, in cassandra.connection.Connection.factory
  File "/home/airflow/.local/lib/python3.8/site-packages/cassandra/io/libevreactor.py", line 266, in __init__
    self._connect_socket()
  File "cassandra/connection.py", line 951, in cassandra.connection.Connection._connect_socket
ConnectionRefusedError: [Errno 111] Tried connecting to [('172.21.0.4', 9042)]. Last error: Connection refused
[2024-04-08T15:11:30.137+0000] {thread.py:57} WARNING - [control connection] Error connecting to 172.21.0.4:9042:
Traceback (most recent call last):
  File "cassandra/cluster.py", line 3577, in cassandra.cluster.ControlConnection._reconnect_internal
  File "cassandra/cluster.py", line 3599, in cassandra.cluster.ControlConnection._try_connect
  File "cassandra/cluster.py", line 1670, in cassandra.cluster.Cluster.connection_factory
  File "cassandra/connection.py", line 846, in cassandra.connection.Connection.factory
  File "/home/airflow/.local/lib/python3.8/site-packages/cassandra/io/libevreactor.py", line 266, in __init__
    self._connect_socket()
  File "cassandra/connection.py", line 951, in cassandra.connection.Connection._connect_socket
ConnectionRefusedError: [Errno 111] Tried connecting to [('172.21.0.4', 9042)]. Last error: Connection refused
[2024-04-08T15:11:30.152+0000] {thread.py:57} WARNING - [control connection] Error connecting to 172.21.0.4:9042:
Traceback (most recent call last):
  File "cassandra/cluster.py", line 3577, in cassandra.cluster.ControlConnection._reconnect_internal
  File "cassandra/cluster.py", line 3599, in cassandra.cluster.ControlConnection._try_connect
  File "cassandra/cluster.py", line 1670, in cassandra.cluster.Cluster.connection_factory
  File "cassandra/connection.py", line 846, in cassandra.connection.Connection.factory
  File "/home/airflow/.local/lib/python3.8/site-packages/cassandra/io/libevreactor.py", line 266, in __init__
    self._connect_socket()
  File "cassandra/connection.py", line 951, in cassandra.connection.Connection._connect_socket
ConnectionRefusedError: [Errno 111] Tried connecting to [('172.21.0.4', 9042)]. Last error: Connection refused
[2024-04-08T15:11:30.229+0000] {thread.py:57} WARNING - [control connection] Error connecting to 172.21.0.4:9042:
Traceback (most recent call last):
  File "cassandra/cluster.py", line 3577, in cassandra.cluster.ControlConnection._reconnect_internal
  File "cassandra/cluster.py", line 3599, in cassandra.cluster.ControlConnection._try_connect
  File "cassandra/cluster.py", line 1670, in cassandra.cluster.Cluster.connection_factory
  File "cassandra/connection.py", line 846, in cassandra.connection.Connection.factory
  File "/home/airflow/.local/lib/python3.8/site-packages/cassandra/io/libevreactor.py", line 266, in __init__
    self._connect_socket()
  File "cassandra/connection.py", line 951, in cassandra.connection.Connection._connect_socket
ConnectionRefusedError: [Errno 111] Tried connecting to [('172.21.0.4', 9042)]. Last error: Connection refused
[2024-04-08T15:11:30.673+0000] {base.py:83} INFO - Using connection ID 'cassandra_conn' for task execution.
[2024-04-08T15:11:30.810+0000] {cassandra.py:128} WARNING - [control connection] Error connecting to 172.21.0.4:9042:
Traceback (most recent call last):
  File "cassandra/cluster.py", line 3577, in cassandra.cluster.ControlConnection._reconnect_internal
  File "cassandra/cluster.py", line 3599, in cassandra.cluster.ControlConnection._try_connect
  File "cassandra/cluster.py", line 1670, in cassandra.cluster.Cluster.connection_factory
  File "cassandra/connection.py", line 846, in cassandra.connection.Connection.factory
  File "/home/airflow/.local/lib/python3.8/site-packages/cassandra/io/libevreactor.py", line 266, in __init__
    self._connect_socket()
  File "cassandra/connection.py", line 951, in cassandra.connection.Connection._connect_socket
ConnectionRefusedError: [Errno 111] Tried connecting to [('172.21.0.4', 9042)]. Last error: Connection refused
[2024-04-08T15:11:30.822+0000] {cassandra.py:128} ERROR - Control connection failed to connect, shutting down Cluster:
Traceback (most recent call last):
  File "cassandra/cluster.py", line 1740, in cassandra.cluster.Cluster.connect
  File "cassandra/cluster.py", line 3543, in cassandra.cluster.ControlConnection.connect
  File "cassandra/cluster.py", line 3588, in cassandra.cluster.ControlConnection._reconnect_internal
cassandra.cluster.NoHostAvailable: ('Unable to connect to any servers', {'172.21.0.4:9042': ConnectionRefusedError(111, "Tried connecting to [('172.21.0.4', 9042)]. Last error: Connection refused")})
[2024-04-08T15:11:37.060+0000] {thread.py:57} WARNING - [control connection] Error connecting to 172.21.0.4:9042:
Traceback (most recent call last):
  File "cassandra/cluster.py", line 3577, in cassandra.cluster.ControlConnection._reconnect_internal
  File "cassandra/cluster.py", line 3599, in cassandra.cluster.ControlConnection._try_connect
  File "cassandra/cluster.py", line 1670, in cassandra.cluster.Cluster.connection_factory
  File "cassandra/connection.py", line 846, in cassandra.connection.Connection.factory
  File "/home/airflow/.local/lib/python3.8/site-packages/cassandra/io/libevreactor.py", line 266, in __init__
    self._connect_socket()
  File "cassandra/connection.py", line 951, in cassandra.connection.Connection._connect_socket
OSError: [Errno None] Tried connecting to [('172.21.0.4', 9042)]. Last error: timed out
[2024-04-08T15:11:37.070+0000] {thread.py:57} WARNING - [control connection] Error connecting to 172.21.0.4:9042:
Traceback (most recent call last):
  File "cassandra/cluster.py", line 3577, in cassandra.cluster.ControlConnection._reconnect_internal
  File "cassandra/cluster.py", line 3599, in cassandra.cluster.ControlConnection._try_connect
  File "cassandra/cluster.py", line 1670, in cassandra.cluster.Cluster.connection_factory
  File "cassandra/connection.py", line 846, in cassandra.connection.Connection.factory
  File "/home/airflow/.local/lib/python3.8/site-packages/cassandra/io/libevreactor.py", line 266, in __init__
    self._connect_socket()
  File "cassandra/connection.py", line 951, in cassandra.connection.Connection._connect_socket
OSError: [Errno None] Tried connecting to [('172.21.0.4', 9042)]. Last error: timed out
[2024-04-08T15:11:37.077+0000] {thread.py:57} WARNING - [control connection] Error connecting to 172.21.0.4:9042:
Traceback (most recent call last):
  File "cassandra/cluster.py", line 3577, in cassandra.cluster.ControlConnection._reconnect_internal
  File "cassandra/cluster.py", line 3599, in cassandra.cluster.ControlConnection._try_connect
  File "cassandra/cluster.py", line 1670, in cassandra.cluster.Cluster.connection_factory
  File "cassandra/connection.py", line 846, in cassandra.connection.Connection.factory
  File "/home/airflow/.local/lib/python3.8/site-packages/cassandra/io/libevreactor.py", line 266, in __init__
    self._connect_socket()
  File "cassandra/connection.py", line 951, in cassandra.connection.Connection._connect_socket
OSError: [Errno None] Tried connecting to [('172.21.0.4', 9042)]. Last error: timed out
[2024-04-08T15:11:37.200+0000] {thread.py:57} WARNING - [control connection] Error connecting to 172.21.0.4:9042:
Traceback (most recent call last):
  File "cassandra/cluster.py", line 3577, in cassandra.cluster.ControlConnection._reconnect_internal
  File "cassandra/cluster.py", line 3599, in cassandra.cluster.ControlConnection._try_connect
  File "cassandra/cluster.py", line 1670, in cassandra.cluster.Cluster.connection_factory
  File "cassandra/connection.py", line 846, in cassandra.connection.Connection.factory
  File "/home/airflow/.local/lib/python3.8/site-packages/cassandra/io/libevreactor.py", line 266, in __init__
    self._connect_socket()
  File "cassandra/connection.py", line 951, in cassandra.connection.Connection._connect_socket
OSError: [Errno None] Tried connecting to [('172.21.0.4', 9042)]. Last error: timed out
[2024-04-08T15:11:37.364+0000] {thread.py:57} WARNING - [control connection] Error connecting to 172.21.0.4:9042:
Traceback (most recent call last):
  File "cassandra/cluster.py", line 3577, in cassandra.cluster.ControlConnection._reconnect_internal
  File "cassandra/cluster.py", line 3599, in cassandra.cluster.ControlConnection._try_connect
  File "cassandra/cluster.py", line 1670, in cassandra.cluster.Cluster.connection_factory
  File "cassandra/connection.py", line 846, in cassandra.connection.Connection.factory
  File "/home/airflow/.local/lib/python3.8/site-packages/cassandra/io/libevreactor.py", line 266, in __init__
    self._connect_socket()
  File "cassandra/connection.py", line 951, in cassandra.connection.Connection._connect_socket
OSError: [Errno None] Tried connecting to [('172.21.0.4', 9042)]. Last error: timed out
[2024-04-08T15:11:43.542+0000] {thread.py:57} WARNING - [control connection] Error connecting to 172.21.0.4:9042:
Traceback (most recent call last):
  File "cassandra/cluster.py", line 3577, in cassandra.cluster.ControlConnection._reconnect_internal
  File "cassandra/cluster.py", line 3599, in cassandra.cluster.ControlConnection._try_connect
  File "cassandra/cluster.py", line 1670, in cassandra.cluster.Cluster.connection_factory
  File "cassandra/connection.py", line 846, in cassandra.connection.Connection.factory
  File "/home/airflow/.local/lib/python3.8/site-packages/cassandra/io/libevreactor.py", line 266, in __init__
    self._connect_socket()
  File "cassandra/connection.py", line 951, in cassandra.connection.Connection._connect_socket
OSError: [Errno 113] Tried connecting to [('172.21.0.4', 9042)]. Last error: No route to host
[2024-04-08T15:11:43.544+0000] {thread.py:57} WARNING - [control connection] Error connecting to 172.21.0.4:9042:
Traceback (most recent call last):
  File "cassandra/cluster.py", line 3577, in cassandra.cluster.ControlConnection._reconnect_internal
  File "cassandra/cluster.py", line 3599, in cassandra.cluster.ControlConnection._try_connect
  File "cassandra/cluster.py", line 1670, in cassandra.cluster.Cluster.connection_factory
  File "cassandra/connection.py", line 846, in cassandra.connection.Connection.factory
  File "/home/airflow/.local/lib/python3.8/site-packages/cassandra/io/libevreactor.py", line 266, in __init__
    self._connect_socket()
  File "cassandra/connection.py", line 951, in cassandra.connection.Connection._connect_socket
OSError: [Errno 113] Tried connecting to [('172.21.0.4', 9042)]. Last error: No route to host
[2024-04-08T15:11:43.545+0000] {thread.py:57} WARNING - [control connection] Error connecting to 172.21.0.4:9042:
Traceback (most recent call last):
  File "cassandra/cluster.py", line 3577, in cassandra.cluster.ControlConnection._reconnect_internal
  File "cassandra/cluster.py", line 3599, in cassandra.cluster.ControlConnection._try_connect
  File "cassandra/cluster.py", line 1670, in cassandra.cluster.Cluster.connection_factory
  File "cassandra/connection.py", line 846, in cassandra.connection.Connection.factory
  File "/home/airflow/.local/lib/python3.8/site-packages/cassandra/io/libevreactor.py", line 266, in __init__
    self._connect_socket()
  File "cassandra/connection.py", line 951, in cassandra.connection.Connection._connect_socket
OSError: [Errno 113] Tried connecting to [('172.21.0.4', 9042)]. Last error: No route to host
[2024-04-08T15:11:43.545+0000] {thread.py:57} WARNING - [control connection] Error connecting to 172.21.0.4:9042:
Traceback (most recent call last):
  File "cassandra/cluster.py", line 3577, in cassandra.cluster.ControlConnection._reconnect_internal
  File "cassandra/cluster.py", line 3599, in cassandra.cluster.ControlConnection._try_connect
  File "cassandra/cluster.py", line 1670, in cassandra.cluster.Cluster.connection_factory
  File "cassandra/connection.py", line 846, in cassandra.connection.Connection.factory
  File "/home/airflow/.local/lib/python3.8/site-packages/cassandra/io/libevreactor.py", line 266, in __init__
    self._connect_socket()
  File "cassandra/connection.py", line 951, in cassandra.connection.Connection._connect_socket
OSError: [Errno 113] Tried connecting to [('172.21.0.4', 9042)]. Last error: No route to host
[2024-04-08T15:11:46.692+0000] {thread.py:57} WARNING - [control connection] Error connecting to 172.21.0.4:9042:
Traceback (most recent call last):
  File "cassandra/cluster.py", line 3577, in cassandra.cluster.ControlConnection._reconnect_internal
  File "cassandra/cluster.py", line 3599, in cassandra.cluster.ControlConnection._try_connect
  File "cassandra/cluster.py", line 1670, in cassandra.cluster.Cluster.connection_factory
  File "cassandra/connection.py", line 846, in cassandra.connection.Connection.factory
  File "/home/airflow/.local/lib/python3.8/site-packages/cassandra/io/libevreactor.py", line 266, in __init__
    self._connect_socket()
  File "cassandra/connection.py", line 951, in cassandra.connection.Connection._connect_socket
OSError: [Errno None] Tried connecting to [('172.21.0.4', 9042)]. Last error: timed out
[2024-04-08T15:11:53.462+0000] {thread.py:57} WARNING - [control connection] Error connecting to 172.21.0.4:9042:
Traceback (most recent call last):
  File "cassandra/cluster.py", line 3577, in cassandra.cluster.ControlConnection._reconnect_internal
  File "cassandra/cluster.py", line 3599, in cassandra.cluster.ControlConnection._try_connect
  File "cassandra/cluster.py", line 1670, in cassandra.cluster.Cluster.connection_factory
  File "cassandra/connection.py", line 846, in cassandra.connection.Connection.factory
  File "/home/airflow/.local/lib/python3.8/site-packages/cassandra/io/libevreactor.py", line 266, in __init__
    self._connect_socket()
  File "cassandra/connection.py", line 951, in cassandra.connection.Connection._connect_socket
OSError: [Errno 113] Tried connecting to [('172.21.0.4', 9042)]. Last error: No route to host
[2024-04-08T15:11:53.464+0000] {thread.py:57} WARNING - [control connection] Error connecting to 172.21.0.4:9042:
Traceback (most recent call last):
  File "cassandra/cluster.py", line 3577, in cassandra.cluster.ControlConnection._reconnect_internal
  File "cassandra/cluster.py", line 3599, in cassandra.cluster.ControlConnection._try_connect
  File "cassandra/cluster.py", line 1670, in cassandra.cluster.Cluster.connection_factory
  File "cassandra/connection.py", line 846, in cassandra.connection.Connection.factory
  File "/home/airflow/.local/lib/python3.8/site-packages/cassandra/io/libevreactor.py", line 266, in __init__
    self._connect_socket()
  File "cassandra/connection.py", line 951, in cassandra.connection.Connection._connect_socket
OSError: [Errno 113] Tried connecting to [('172.21.0.4', 9042)]. Last error: No route to host
[2024-04-08T15:11:53.465+0000] {thread.py:57} WARNING - [control connection] Error connecting to 172.21.0.4:9042:
Traceback (most recent call last):
  File "cassandra/cluster.py", line 3577, in cassandra.cluster.ControlConnection._reconnect_internal
  File "cassandra/cluster.py", line 3599, in cassandra.cluster.ControlConnection._try_connect
  File "cassandra/cluster.py", line 1670, in cassandra.cluster.Cluster.connection_factory
  File "cassandra/connection.py", line 846, in cassandra.connection.Connection.factory
  File "/home/airflow/.local/lib/python3.8/site-packages/cassandra/io/libevreactor.py", line 266, in __init__
    self._connect_socket()
  File "cassandra/connection.py", line 951, in cassandra.connection.Connection._connect_socket
OSError: [Errno 113] Tried connecting to [('172.21.0.4', 9042)]. Last error: No route to host
[2024-04-08T15:11:53.466+0000] {thread.py:57} WARNING - [control connection] Error connecting to 172.21.0.4:9042:
Traceback (most recent call last):
  File "cassandra/cluster.py", line 3577, in cassandra.cluster.ControlConnection._reconnect_internal
  File "cassandra/cluster.py", line 3599, in cassandra.cluster.ControlConnection._try_connect
  File "cassandra/cluster.py", line 1670, in cassandra.cluster.Cluster.connection_factory
  File "cassandra/connection.py", line 846, in cassandra.connection.Connection.factory
  File "/home/airflow/.local/lib/python3.8/site-packages/cassandra/io/libevreactor.py", line 266, in __init__
    self._connect_socket()
  File "cassandra/connection.py", line 951, in cassandra.connection.Connection._connect_socket
OSError: [Errno 113] Tried connecting to [('172.21.0.4', 9042)]. Last error: No route to host
[2024-04-08T15:11:59.716+0000] {thread.py:57} WARNING - [control connection] Error connecting to 172.21.0.4:9042:
Traceback (most recent call last):
  File "cassandra/cluster.py", line 3577, in cassandra.cluster.ControlConnection._reconnect_internal
  File "cassandra/cluster.py", line 3599, in cassandra.cluster.ControlConnection._try_connect
  File "cassandra/cluster.py", line 1670, in cassandra.cluster.Cluster.connection_factory
  File "cassandra/connection.py", line 846, in cassandra.connection.Connection.factory
  File "/home/airflow/.local/lib/python3.8/site-packages/cassandra/io/libevreactor.py", line 266, in __init__
    self._connect_socket()
  File "cassandra/connection.py", line 951, in cassandra.connection.Connection._connect_socket
OSError: [Errno 113] Tried connecting to [('172.21.0.4', 9042)]. Last error: No route to host
[2024-04-08T15:11:59.718+0000] {thread.py:57} WARNING - [control connection] Error connecting to 172.21.0.4:9042:
Traceback (most recent call last):
  File "cassandra/cluster.py", line 3577, in cassandra.cluster.ControlConnection._reconnect_internal
  File "cassandra/cluster.py", line 3599, in cassandra.cluster.ControlConnection._try_connect
  File "cassandra/cluster.py", line 1670, in cassandra.cluster.Cluster.connection_factory
  File "cassandra/connection.py", line 846, in cassandra.connection.Connection.factory
  File "/home/airflow/.local/lib/python3.8/site-packages/cassandra/io/libevreactor.py", line 266, in __init__
    self._connect_socket()
  File "cassandra/connection.py", line 951, in cassandra.connection.Connection._connect_socket
OSError: [Errno 113] Tried connecting to [('172.21.0.4', 9042)]. Last error: No route to host
[2024-04-08T15:11:59.719+0000] {thread.py:57} WARNING - [control connection] Error connecting to 172.21.0.4:9042:
Traceback (most recent call last):
  File "cassandra/cluster.py", line 3577, in cassandra.cluster.ControlConnection._reconnect_internal
  File "cassandra/cluster.py", line 3599, in cassandra.cluster.ControlConnection._try_connect
  File "cassandra/cluster.py", line 1670, in cassandra.cluster.Cluster.connection_factory
  File "cassandra/connection.py", line 846, in cassandra.connection.Connection.factory
  File "/home/airflow/.local/lib/python3.8/site-packages/cassandra/io/libevreactor.py", line 266, in __init__
    self._connect_socket()
  File "cassandra/connection.py", line 951, in cassandra.connection.Connection._connect_socket
OSError: [Errno 113] Tried connecting to [('172.21.0.4', 9042)]. Last error: No route to host
[2024-04-08T15:11:59.719+0000] {thread.py:57} WARNING - [control connection] Error connecting to 172.21.0.4:9042:
Traceback (most recent call last):
  File "cassandra/cluster.py", line 3577, in cassandra.cluster.ControlConnection._reconnect_internal
  File "cassandra/cluster.py", line 3599, in cassandra.cluster.ControlConnection._try_connect
  File "cassandra/cluster.py", line 1670, in cassandra.cluster.Cluster.connection_factory
  File "cassandra/connection.py", line 846, in cassandra.connection.Connection.factory
  File "/home/airflow/.local/lib/python3.8/site-packages/cassandra/io/libevreactor.py", line 266, in __init__
    self._connect_socket()
  File "cassandra/connection.py", line 951, in cassandra.connection.Connection._connect_socket
OSError: [Errno 113] Tried connecting to [('172.21.0.4', 9042)]. Last error: No route to host
[2024-04-08T15:12:02.836+0000] {thread.py:57} WARNING - [control connection] Error connecting to 172.21.0.4:9042:
Traceback (most recent call last):
  File "cassandra/cluster.py", line 3577, in cassandra.cluster.ControlConnection._reconnect_internal
  File "cassandra/cluster.py", line 3599, in cassandra.cluster.ControlConnection._try_connect
  File "cassandra/cluster.py", line 1670, in cassandra.cluster.Cluster.connection_factory
  File "cassandra/connection.py", line 846, in cassandra.connection.Connection.factory
  File "/home/airflow/.local/lib/python3.8/site-packages/cassandra/io/libevreactor.py", line 266, in __init__
    self._connect_socket()
  File "cassandra/connection.py", line 951, in cassandra.connection.Connection._connect_socket
OSError: [Errno 113] Tried connecting to [('172.21.0.4', 9042)]. Last error: No route to host
[2024-04-08T15:12:02.846+0000] {thread.py:57} WARNING - [control connection] Error connecting to 172.21.0.4:9042:
Traceback (most recent call last):
  File "cassandra/cluster.py", line 3577, in cassandra.cluster.ControlConnection._reconnect_internal
  File "cassandra/cluster.py", line 3599, in cassandra.cluster.ControlConnection._try_connect
  File "cassandra/cluster.py", line 1670, in cassandra.cluster.Cluster.connection_factory
  File "cassandra/connection.py", line 846, in cassandra.connection.Connection.factory
  File "/home/airflow/.local/lib/python3.8/site-packages/cassandra/io/libevreactor.py", line 266, in __init__
    self._connect_socket()
  File "cassandra/connection.py", line 951, in cassandra.connection.Connection._connect_socket
OSError: [Errno 113] Tried connecting to [('172.21.0.4', 9042)]. Last error: No route to host
[2024-04-08T15:12:02.851+0000] {thread.py:57} WARNING - [control connection] Error connecting to 172.21.0.4:9042:
Traceback (most recent call last):
  File "cassandra/cluster.py", line 3577, in cassandra.cluster.ControlConnection._reconnect_internal
  File "cassandra/cluster.py", line 3599, in cassandra.cluster.ControlConnection._try_connect
  File "cassandra/cluster.py", line 1670, in cassandra.cluster.Cluster.connection_factory
  File "cassandra/connection.py", line 846, in cassandra.connection.Connection.factory
  File "/home/airflow/.local/lib/python3.8/site-packages/cassandra/io/libevreactor.py", line 266, in __init__
    self._connect_socket()
  File "cassandra/connection.py", line 951, in cassandra.connection.Connection._connect_socket
OSError: [Errno 113] Tried connecting to [('172.21.0.4', 9042)]. Last error: No route to host
[2024-04-08T15:12:05.831+0000] {thread.py:57} WARNING - [control connection] Error connecting to 172.21.0.4:9042:
Traceback (most recent call last):
  File "cassandra/cluster.py", line 3577, in cassandra.cluster.ControlConnection._reconnect_internal
  File "cassandra/cluster.py", line 3599, in cassandra.cluster.ControlConnection._try_connect
  File "cassandra/cluster.py", line 1670, in cassandra.cluster.Cluster.connection_factory
  File "cassandra/connection.py", line 846, in cassandra.connection.Connection.factory
  File "/home/airflow/.local/lib/python3.8/site-packages/cassandra/io/libevreactor.py", line 266, in __init__
    self._connect_socket()
  File "cassandra/connection.py", line 951, in cassandra.connection.Connection._connect_socket
OSError: [Errno None] Tried connecting to [('172.21.0.4', 9042)]. Last error: timed out
[2024-04-08T15:12:05.914+0000] {thread.py:57} WARNING - [control connection] Error connecting to 172.21.0.4:9042:
Traceback (most recent call last):
  File "cassandra/cluster.py", line 3577, in cassandra.cluster.ControlConnection._reconnect_internal
  File "cassandra/cluster.py", line 3599, in cassandra.cluster.ControlConnection._try_connect
  File "cassandra/cluster.py", line 1670, in cassandra.cluster.Cluster.connection_factory
  File "cassandra/connection.py", line 846, in cassandra.connection.Connection.factory
  File "/home/airflow/.local/lib/python3.8/site-packages/cassandra/io/libevreactor.py", line 266, in __init__
    self._connect_socket()
  File "cassandra/connection.py", line 951, in cassandra.connection.Connection._connect_socket
OSError: [Errno None] Tried connecting to [('172.21.0.4', 9042)]. Last error: timed out
[2024-04-08T15:12:05.956+0000] {thread.py:57} WARNING - [control connection] Error connecting to 172.21.0.4:9042:
Traceback (most recent call last):
  File "cassandra/cluster.py", line 3577, in cassandra.cluster.ControlConnection._reconnect_internal
  File "cassandra/cluster.py", line 3599, in cassandra.cluster.ControlConnection._try_connect
  File "cassandra/cluster.py", line 1670, in cassandra.cluster.Cluster.connection_factory
  File "cassandra/connection.py", line 846, in cassandra.connection.Connection.factory
  File "/home/airflow/.local/lib/python3.8/site-packages/cassandra/io/libevreactor.py", line 266, in __init__
    self._connect_socket()
  File "cassandra/connection.py", line 951, in cassandra.connection.Connection._connect_socket
OSError: [Errno 113] Tried connecting to [('172.21.0.4', 9042)]. Last error: No route to host
[2024-04-08T15:12:05.957+0000] {thread.py:57} WARNING - [control connection] Error connecting to 172.21.0.4:9042:
Traceback (most recent call last):
  File "cassandra/cluster.py", line 3577, in cassandra.cluster.ControlConnection._reconnect_internal
  File "cassandra/cluster.py", line 3599, in cassandra.cluster.ControlConnection._try_connect
  File "cassandra/cluster.py", line 1670, in cassandra.cluster.Cluster.connection_factory
  File "cassandra/connection.py", line 846, in cassandra.connection.Connection.factory
  File "/home/airflow/.local/lib/python3.8/site-packages/cassandra/io/libevreactor.py", line 266, in __init__
    self._connect_socket()
  File "cassandra/connection.py", line 951, in cassandra.connection.Connection._connect_socket
OSError: [Errno 113] Tried connecting to [('172.21.0.4', 9042)]. Last error: No route to host
[2024-04-08T15:12:09.837+0000] {thread.py:57} WARNING - [control connection] Error connecting to 172.21.0.4:9042:
Traceback (most recent call last):
  File "cassandra/cluster.py", line 3577, in cassandra.cluster.ControlConnection._reconnect_internal
  File "cassandra/cluster.py", line 3599, in cassandra.cluster.ControlConnection._try_connect
  File "cassandra/cluster.py", line 1670, in cassandra.cluster.Cluster.connection_factory
  File "cassandra/connection.py", line 846, in cassandra.connection.Connection.factory
  File "/home/airflow/.local/lib/python3.8/site-packages/cassandra/io/libevreactor.py", line 266, in __init__
    self._connect_socket()
  File "cassandra/connection.py", line 951, in cassandra.connection.Connection._connect_socket
OSError: [Errno None] Tried connecting to [('172.21.0.4', 9042)]. Last error: timed out
[2024-04-08T15:12:12.187+0000] {thread.py:57} WARNING - [control connection] Error connecting to 172.21.0.4:9042:
Traceback (most recent call last):
  File "cassandra/cluster.py", line 3577, in cassandra.cluster.ControlConnection._reconnect_internal
  File "cassandra/cluster.py", line 3599, in cassandra.cluster.ControlConnection._try_connect
  File "cassandra/cluster.py", line 1670, in cassandra.cluster.Cluster.connection_factory
  File "cassandra/connection.py", line 846, in cassandra.connection.Connection.factory
  File "/home/airflow/.local/lib/python3.8/site-packages/cassandra/io/libevreactor.py", line 266, in __init__
    self._connect_socket()
  File "cassandra/connection.py", line 951, in cassandra.connection.Connection._connect_socket
OSError: [Errno 113] Tried connecting to [('172.21.0.4', 9042)]. Last error: No route to host
[2024-04-08T15:12:12.188+0000] {thread.py:57} WARNING - [control connection] Error connecting to 172.21.0.4:9042:
Traceback (most recent call last):
  File "cassandra/cluster.py", line 3577, in cassandra.cluster.ControlConnection._reconnect_internal
  File "cassandra/cluster.py", line 3599, in cassandra.cluster.ControlConnection._try_connect
  File "cassandra/cluster.py", line 1670, in cassandra.cluster.Cluster.connection_factory
  File "cassandra/connection.py", line 846, in cassandra.connection.Connection.factory
  File "/home/airflow/.local/lib/python3.8/site-packages/cassandra/io/libevreactor.py", line 266, in __init__
    self._connect_socket()
  File "cassandra/connection.py", line 951, in cassandra.connection.Connection._connect_socket
OSError: [Errno 113] Tried connecting to [('172.21.0.4', 9042)]. Last error: No route to host
[2024-04-08T15:12:12.189+0000] {thread.py:57} WARNING - [control connection] Error connecting to 172.21.0.4:9042:
Traceback (most recent call last):
  File "cassandra/cluster.py", line 3577, in cassandra.cluster.ControlConnection._reconnect_internal
  File "cassandra/cluster.py", line 3599, in cassandra.cluster.ControlConnection._try_connect
  File "cassandra/cluster.py", line 1670, in cassandra.cluster.Cluster.connection_factory
  File "cassandra/connection.py", line 846, in cassandra.connection.Connection.factory
  File "/home/airflow/.local/lib/python3.8/site-packages/cassandra/io/libevreactor.py", line 266, in __init__
    self._connect_socket()
  File "cassandra/connection.py", line 951, in cassandra.connection.Connection._connect_socket
OSError: [Errno 113] Tried connecting to [('172.21.0.4', 9042)]. Last error: No route to host
[2024-04-08T15:12:12.189+0000] {thread.py:57} WARNING - [control connection] Error connecting to 172.21.0.4:9042:
Traceback (most recent call last):
  File "cassandra/cluster.py", line 3577, in cassandra.cluster.ControlConnection._reconnect_internal
  File "cassandra/cluster.py", line 3599, in cassandra.cluster.ControlConnection._try_connect
  File "cassandra/cluster.py", line 1670, in cassandra.cluster.Cluster.connection_factory
  File "cassandra/connection.py", line 846, in cassandra.connection.Connection.factory
  File "/home/airflow/.local/lib/python3.8/site-packages/cassandra/io/libevreactor.py", line 266, in __init__
    self._connect_socket()
  File "cassandra/connection.py", line 951, in cassandra.connection.Connection._connect_socket
OSError: [Errno 113] Tried connecting to [('172.21.0.4', 9042)]. Last error: No route to host
[2024-04-08T15:12:15.307+0000] {thread.py:57} WARNING - [control connection] Error connecting to 172.21.0.4:9042:
Traceback (most recent call last):
  File "cassandra/cluster.py", line 3577, in cassandra.cluster.ControlConnection._reconnect_internal
  File "cassandra/cluster.py", line 3599, in cassandra.cluster.ControlConnection._try_connect
  File "cassandra/cluster.py", line 1670, in cassandra.cluster.Cluster.connection_factory
  File "cassandra/connection.py", line 846, in cassandra.connection.Connection.factory
  File "/home/airflow/.local/lib/python3.8/site-packages/cassandra/io/libevreactor.py", line 266, in __init__
    self._connect_socket()
  File "cassandra/connection.py", line 951, in cassandra.connection.Connection._connect_socket
OSError: [Errno 113] Tried connecting to [('172.21.0.4', 9042)]. Last error: No route to host
[2024-04-08T15:12:18.427+0000] {thread.py:57} WARNING - [control connection] Error connecting to 172.21.0.4:9042:
Traceback (most recent call last):
  File "cassandra/cluster.py", line 3577, in cassandra.cluster.ControlConnection._reconnect_internal
  File "cassandra/cluster.py", line 3599, in cassandra.cluster.ControlConnection._try_connect
  File "cassandra/cluster.py", line 1670, in cassandra.cluster.Cluster.connection_factory
  File "cassandra/connection.py", line 846, in cassandra.connection.Connection.factory
  File "/home/airflow/.local/lib/python3.8/site-packages/cassandra/io/libevreactor.py", line 266, in __init__
    self._connect_socket()
  File "cassandra/connection.py", line 951, in cassandra.connection.Connection._connect_socket
OSError: [Errno 113] Tried connecting to [('172.21.0.4', 9042)]. Last error: No route to host
[2024-04-08T15:12:18.428+0000] {thread.py:57} WARNING - [control connection] Error connecting to 172.21.0.4:9042:
Traceback (most recent call last):
  File "cassandra/cluster.py", line 3577, in cassandra.cluster.ControlConnection._reconnect_internal
  File "cassandra/cluster.py", line 3599, in cassandra.cluster.ControlConnection._try_connect
  File "cassandra/cluster.py", line 1670, in cassandra.cluster.Cluster.connection_factory
  File "cassandra/connection.py", line 846, in cassandra.connection.Connection.factory
  File "/home/airflow/.local/lib/python3.8/site-packages/cassandra/io/libevreactor.py", line 266, in __init__
    self._connect_socket()
  File "cassandra/connection.py", line 951, in cassandra.connection.Connection._connect_socket
OSError: [Errno 113] Tried connecting to [('172.21.0.4', 9042)]. Last error: No route to host
[2024-04-08T15:12:18.430+0000] {thread.py:57} WARNING - [control connection] Error connecting to 172.21.0.4:9042:
Traceback (most recent call last):
  File "cassandra/cluster.py", line 3577, in cassandra.cluster.ControlConnection._reconnect_internal
  File "cassandra/cluster.py", line 3599, in cassandra.cluster.ControlConnection._try_connect
  File "cassandra/cluster.py", line 1670, in cassandra.cluster.Cluster.connection_factory
  File "cassandra/connection.py", line 846, in cassandra.connection.Connection.factory
  File "/home/airflow/.local/lib/python3.8/site-packages/cassandra/io/libevreactor.py", line 266, in __init__
    self._connect_socket()
  File "cassandra/connection.py", line 951, in cassandra.connection.Connection._connect_socket
OSError: [Errno 113] Tried connecting to [('172.21.0.4', 9042)]. Last error: No route to host
[2024-04-08T15:12:21.546+0000] {thread.py:57} WARNING - [control connection] Error connecting to 172.21.0.4:9042:
Traceback (most recent call last):
  File "cassandra/cluster.py", line 3577, in cassandra.cluster.ControlConnection._reconnect_internal
  File "cassandra/cluster.py", line 3599, in cassandra.cluster.ControlConnection._try_connect
  File "cassandra/cluster.py", line 1670, in cassandra.cluster.Cluster.connection_factory
  File "cassandra/connection.py", line 846, in cassandra.connection.Connection.factory
  File "/home/airflow/.local/lib/python3.8/site-packages/cassandra/io/libevreactor.py", line 266, in __init__
    self._connect_socket()
  File "cassandra/connection.py", line 951, in cassandra.connection.Connection._connect_socket
OSError: [Errno 113] Tried connecting to [('172.21.0.4', 9042)]. Last error: No route to host
[2024-04-08T15:12:25.477+0000] {thread.py:57} WARNING - [control connection] Error connecting to 172.21.0.4:9042:
Traceback (most recent call last):
  File "cassandra/cluster.py", line 3577, in cassandra.cluster.ControlConnection._reconnect_internal
  File "cassandra/cluster.py", line 3599, in cassandra.cluster.ControlConnection._try_connect
  File "cassandra/cluster.py", line 1670, in cassandra.cluster.Cluster.connection_factory
  File "cassandra/connection.py", line 846, in cassandra.connection.Connection.factory
  File "/home/airflow/.local/lib/python3.8/site-packages/cassandra/io/libevreactor.py", line 266, in __init__
    self._connect_socket()
  File "cassandra/connection.py", line 951, in cassandra.connection.Connection._connect_socket
OSError: [Errno 113] Tried connecting to [('172.21.0.4', 9042)]. Last error: No route to host
[2024-04-08T15:12:25.478+0000] {thread.py:57} WARNING - [control connection] Error connecting to 172.21.0.4:9042:
Traceback (most recent call last):
  File "cassandra/cluster.py", line 3577, in cassandra.cluster.ControlConnection._reconnect_internal
  File "cassandra/cluster.py", line 3599, in cassandra.cluster.ControlConnection._try_connect
  File "cassandra/cluster.py", line 1670, in cassandra.cluster.Cluster.connection_factory
  File "cassandra/connection.py", line 846, in cassandra.connection.Connection.factory
  File "/home/airflow/.local/lib/python3.8/site-packages/cassandra/io/libevreactor.py", line 266, in __init__
    self._connect_socket()
  File "cassandra/connection.py", line 951, in cassandra.connection.Connection._connect_socket
OSError: [Errno 113] Tried connecting to [('172.21.0.4', 9042)]. Last error: No route to host
[2024-04-08T15:12:26.265+0000] {thread.py:57} WARNING - [control connection] Error connecting to 172.21.0.4:9042:
Traceback (most recent call last):
  File "cassandra/cluster.py", line 3577, in cassandra.cluster.ControlConnection._reconnect_internal
  File "cassandra/cluster.py", line 3599, in cassandra.cluster.ControlConnection._try_connect
  File "cassandra/cluster.py", line 1670, in cassandra.cluster.Cluster.connection_factory
  File "cassandra/connection.py", line 846, in cassandra.connection.Connection.factory
  File "/home/airflow/.local/lib/python3.8/site-packages/cassandra/io/libevreactor.py", line 266, in __init__
    self._connect_socket()
  File "cassandra/connection.py", line 951, in cassandra.connection.Connection._connect_socket
ConnectionRefusedError: [Errno 111] Tried connecting to [('172.21.0.4', 9042)]. Last error: Connection refused
[2024-04-08T15:12:27.078+0000] {thread.py:57} WARNING - [control connection] Error connecting to 172.21.0.4:9042:
Traceback (most recent call last):
  File "cassandra/cluster.py", line 3577, in cassandra.cluster.ControlConnection._reconnect_internal
  File "cassandra/cluster.py", line 3599, in cassandra.cluster.ControlConnection._try_connect
  File "cassandra/cluster.py", line 1670, in cassandra.cluster.Cluster.connection_factory
  File "cassandra/connection.py", line 846, in cassandra.connection.Connection.factory
  File "/home/airflow/.local/lib/python3.8/site-packages/cassandra/io/libevreactor.py", line 266, in __init__
    self._connect_socket()
  File "cassandra/connection.py", line 951, in cassandra.connection.Connection._connect_socket
ConnectionRefusedError: [Errno 111] Tried connecting to [('172.21.0.4', 9042)]. Last error: Connection refused
[2024-04-08T15:12:28.903+0000] {thread.py:57} WARNING - [control connection] Error connecting to 172.21.0.4:9042:
Traceback (most recent call last):
  File "cassandra/cluster.py", line 3577, in cassandra.cluster.ControlConnection._reconnect_internal
  File "cassandra/cluster.py", line 3599, in cassandra.cluster.ControlConnection._try_connect
  File "cassandra/cluster.py", line 1670, in cassandra.cluster.Cluster.connection_factory
  File "cassandra/connection.py", line 846, in cassandra.connection.Connection.factory
  File "/home/airflow/.local/lib/python3.8/site-packages/cassandra/io/libevreactor.py", line 266, in __init__
    self._connect_socket()
  File "cassandra/connection.py", line 951, in cassandra.connection.Connection._connect_socket
ConnectionRefusedError: [Errno 111] Tried connecting to [('172.21.0.4', 9042)]. Last error: Connection refused
[2024-04-08T15:12:28.905+0000] {thread.py:57} WARNING - [control connection] Error connecting to 172.21.0.4:9042:
Traceback (most recent call last):
  File "cassandra/cluster.py", line 3577, in cassandra.cluster.ControlConnection._reconnect_internal
  File "cassandra/cluster.py", line 3599, in cassandra.cluster.ControlConnection._try_connect
  File "cassandra/cluster.py", line 1670, in cassandra.cluster.Cluster.connection_factory
  File "cassandra/connection.py", line 846, in cassandra.connection.Connection.factory
  File "/home/airflow/.local/lib/python3.8/site-packages/cassandra/io/libevreactor.py", line 266, in __init__
    self._connect_socket()
  File "cassandra/connection.py", line 951, in cassandra.connection.Connection._connect_socket
ConnectionRefusedError: [Errno 111] Tried connecting to [('172.21.0.4', 9042)]. Last error: Connection refused
[2024-04-08T15:12:28.907+0000] {thread.py:57} WARNING - [control connection] Error connecting to 172.21.0.4:9042:
Traceback (most recent call last):
  File "cassandra/cluster.py", line 3577, in cassandra.cluster.ControlConnection._reconnect_internal
  File "cassandra/cluster.py", line 3599, in cassandra.cluster.ControlConnection._try_connect
  File "cassandra/cluster.py", line 1670, in cassandra.cluster.Cluster.connection_factory
  File "cassandra/connection.py", line 846, in cassandra.connection.Connection.factory
  File "/home/airflow/.local/lib/python3.8/site-packages/cassandra/io/libevreactor.py", line 266, in __init__
    self._connect_socket()
  File "cassandra/connection.py", line 951, in cassandra.connection.Connection._connect_socket
ConnectionRefusedError: [Errno 111] Tried connecting to [('172.21.0.4', 9042)]. Last error: Connection refused
[2024-04-08T15:12:28.908+0000] {thread.py:57} WARNING - [control connection] Error connecting to 172.21.0.4:9042:
Traceback (most recent call last):
  File "cassandra/cluster.py", line 3577, in cassandra.cluster.ControlConnection._reconnect_internal
  File "cassandra/cluster.py", line 3599, in cassandra.cluster.ControlConnection._try_connect
  File "cassandra/cluster.py", line 1670, in cassandra.cluster.Cluster.connection_factory
  File "cassandra/connection.py", line 846, in cassandra.connection.Connection.factory
  File "/home/airflow/.local/lib/python3.8/site-packages/cassandra/io/libevreactor.py", line 266, in __init__
    self._connect_socket()
  File "cassandra/connection.py", line 951, in cassandra.connection.Connection._connect_socket
ConnectionRefusedError: [Errno 111] Tried connecting to [('172.21.0.4', 9042)]. Last error: Connection refused
[2024-04-08T15:12:28.958+0000] {thread.py:57} WARNING - [control connection] Error connecting to 172.21.0.4:9042:
Traceback (most recent call last):
  File "cassandra/cluster.py", line 3577, in cassandra.cluster.ControlConnection._reconnect_internal
  File "cassandra/cluster.py", line 3599, in cassandra.cluster.ControlConnection._try_connect
  File "cassandra/cluster.py", line 1670, in cassandra.cluster.Cluster.connection_factory
  File "cassandra/connection.py", line 846, in cassandra.connection.Connection.factory
  File "/home/airflow/.local/lib/python3.8/site-packages/cassandra/io/libevreactor.py", line 266, in __init__
    self._connect_socket()
  File "cassandra/connection.py", line 951, in cassandra.connection.Connection._connect_socket
ConnectionRefusedError: [Errno 111] Tried connecting to [('172.21.0.4', 9042)]. Last error: Connection refused
[2024-04-08T15:12:29.983+0000] {thread.py:57} WARNING - [control connection] Error connecting to 172.21.0.4:9042:
Traceback (most recent call last):
  File "cassandra/cluster.py", line 3577, in cassandra.cluster.ControlConnection._reconnect_internal
  File "cassandra/cluster.py", line 3599, in cassandra.cluster.ControlConnection._try_connect
  File "cassandra/cluster.py", line 1670, in cassandra.cluster.Cluster.connection_factory
  File "cassandra/connection.py", line 846, in cassandra.connection.Connection.factory
  File "/home/airflow/.local/lib/python3.8/site-packages/cassandra/io/libevreactor.py", line 266, in __init__
    self._connect_socket()
  File "cassandra/connection.py", line 951, in cassandra.connection.Connection._connect_socket
ConnectionRefusedError: [Errno 111] Tried connecting to [('172.21.0.4', 9042)]. Last error: Connection refused
[2024-04-08T15:12:29.984+0000] {thread.py:57} WARNING - [control connection] Error connecting to 172.21.0.4:9042:
Traceback (most recent call last):
  File "cassandra/cluster.py", line 3577, in cassandra.cluster.ControlConnection._reconnect_internal
  File "cassandra/cluster.py", line 3599, in cassandra.cluster.ControlConnection._try_connect
  File "cassandra/cluster.py", line 1670, in cassandra.cluster.Cluster.connection_factory
  File "cassandra/connection.py", line 846, in cassandra.connection.Connection.factory
  File "/home/airflow/.local/lib/python3.8/site-packages/cassandra/io/libevreactor.py", line 266, in __init__
    self._connect_socket()
  File "cassandra/connection.py", line 951, in cassandra.connection.Connection._connect_socket
ConnectionRefusedError: [Errno 111] Tried connecting to [('172.21.0.4', 9042)]. Last error: Connection refused
[2024-04-08T15:12:29.992+0000] {thread.py:57} WARNING - [control connection] Error connecting to 172.21.0.4:9042:
Traceback (most recent call last):
  File "cassandra/cluster.py", line 3577, in cassandra.cluster.ControlConnection._reconnect_internal
  File "cassandra/cluster.py", line 3599, in cassandra.cluster.ControlConnection._try_connect
  File "cassandra/cluster.py", line 1670, in cassandra.cluster.Cluster.connection_factory
  File "cassandra/connection.py", line 846, in cassandra.connection.Connection.factory
  File "/home/airflow/.local/lib/python3.8/site-packages/cassandra/io/libevreactor.py", line 266, in __init__
    self._connect_socket()
  File "cassandra/connection.py", line 951, in cassandra.connection.Connection._connect_socket
ConnectionRefusedError: [Errno 111] Tried connecting to [('172.21.0.4', 9042)]. Last error: Connection refused
[2024-04-08T15:12:30.002+0000] {thread.py:57} WARNING - [control connection] Error connecting to 172.21.0.4:9042:
Traceback (most recent call last):
  File "cassandra/cluster.py", line 3577, in cassandra.cluster.ControlConnection._reconnect_internal
  File "cassandra/cluster.py", line 3599, in cassandra.cluster.ControlConnection._try_connect
  File "cassandra/cluster.py", line 1670, in cassandra.cluster.Cluster.connection_factory
  File "cassandra/connection.py", line 846, in cassandra.connection.Connection.factory
  File "/home/airflow/.local/lib/python3.8/site-packages/cassandra/io/libevreactor.py", line 266, in __init__
    self._connect_socket()
  File "cassandra/connection.py", line 951, in cassandra.connection.Connection._connect_socket
ConnectionRefusedError: [Errno 111] Tried connecting to [('172.21.0.4', 9042)]. Last error: Connection refused
[2024-04-08T15:12:30.006+0000] {thread.py:57} WARNING - [control connection] Error connecting to 172.21.0.4:9042:
Traceback (most recent call last):
  File "cassandra/cluster.py", line 3577, in cassandra.cluster.ControlConnection._reconnect_internal
  File "cassandra/cluster.py", line 3599, in cassandra.cluster.ControlConnection._try_connect
  File "cassandra/cluster.py", line 1670, in cassandra.cluster.Cluster.connection_factory
  File "cassandra/connection.py", line 846, in cassandra.connection.Connection.factory
  File "/home/airflow/.local/lib/python3.8/site-packages/cassandra/io/libevreactor.py", line 266, in __init__
    self._connect_socket()
  File "cassandra/connection.py", line 951, in cassandra.connection.Connection._connect_socket
ConnectionRefusedError: [Errno 111] Tried connecting to [('172.21.0.4', 9042)]. Last error: Connection refused
[2024-04-08T15:12:30.905+0000] {record.py:71} INFO - Sensor check existence of record: ['user_id', 'age', 'email', 'name']
[2024-04-08T15:12:30.924+0000] {base.py:83} INFO - Using connection ID 'cassandra_conn' for task execution.
[2024-04-08T15:12:30.930+0000] {cassandra.py:128} WARNING - [control connection] Error connecting to 172.21.0.4:9042:
Traceback (most recent call last):
  File "cassandra/cluster.py", line 3577, in cassandra.cluster.ControlConnection._reconnect_internal
  File "cassandra/cluster.py", line 3599, in cassandra.cluster.ControlConnection._try_connect
  File "cassandra/cluster.py", line 1670, in cassandra.cluster.Cluster.connection_factory
  File "cassandra/connection.py", line 846, in cassandra.connection.Connection.factory
  File "/home/airflow/.local/lib/python3.8/site-packages/cassandra/io/libevreactor.py", line 266, in __init__
    self._connect_socket()
  File "cassandra/connection.py", line 951, in cassandra.connection.Connection._connect_socket
ConnectionRefusedError: [Errno 111] Tried connecting to [('172.21.0.4', 9042)]. Last error: Connection refused
[2024-04-08T15:12:30.932+0000] {cassandra.py:128} ERROR - Control connection failed to connect, shutting down Cluster:
Traceback (most recent call last):
  File "cassandra/cluster.py", line 1740, in cassandra.cluster.Cluster.connect
  File "cassandra/cluster.py", line 3543, in cassandra.cluster.ControlConnection.connect
  File "cassandra/cluster.py", line 3588, in cassandra.cluster.ControlConnection._reconnect_internal
cassandra.cluster.NoHostAvailable: ('Unable to connect to any servers', {'172.21.0.4:9042': ConnectionRefusedError(111, "Tried connecting to [('172.21.0.4', 9042)]. Last error: Connection refused")})
[2024-04-08T15:12:31.789+0000] {thread.py:57} WARNING - [control connection] Error connecting to 172.21.0.4:9042:
Traceback (most recent call last):
  File "cassandra/cluster.py", line 3577, in cassandra.cluster.ControlConnection._reconnect_internal
  File "cassandra/cluster.py", line 3599, in cassandra.cluster.ControlConnection._try_connect
  File "cassandra/cluster.py", line 1670, in cassandra.cluster.Cluster.connection_factory
  File "cassandra/connection.py", line 846, in cassandra.connection.Connection.factory
  File "/home/airflow/.local/lib/python3.8/site-packages/cassandra/io/libevreactor.py", line 266, in __init__
    self._connect_socket()
  File "cassandra/connection.py", line 951, in cassandra.connection.Connection._connect_socket
ConnectionRefusedError: [Errno 111] Tried connecting to [('172.21.0.4', 9042)]. Last error: Connection refused
[2024-04-08T15:12:31.790+0000] {thread.py:57} WARNING - [control connection] Error connecting to 172.21.0.4:9042:
Traceback (most recent call last):
  File "cassandra/cluster.py", line 3577, in cassandra.cluster.ControlConnection._reconnect_internal
  File "cassandra/cluster.py", line 3599, in cassandra.cluster.ControlConnection._try_connect
  File "cassandra/cluster.py", line 1670, in cassandra.cluster.Cluster.connection_factory
  File "cassandra/connection.py", line 846, in cassandra.connection.Connection.factory
  File "/home/airflow/.local/lib/python3.8/site-packages/cassandra/io/libevreactor.py", line 266, in __init__
    self._connect_socket()
  File "cassandra/connection.py", line 951, in cassandra.connection.Connection._connect_socket
ConnectionRefusedError: [Errno 111] Tried connecting to [('172.21.0.4', 9042)]. Last error: Connection refused
[2024-04-08T15:12:31.798+0000] {thread.py:57} WARNING - [control connection] Error connecting to 172.21.0.4:9042:
Traceback (most recent call last):
  File "cassandra/cluster.py", line 3577, in cassandra.cluster.ControlConnection._reconnect_internal
  File "cassandra/cluster.py", line 3599, in cassandra.cluster.ControlConnection._try_connect
  File "cassandra/cluster.py", line 1670, in cassandra.cluster.Cluster.connection_factory
  File "cassandra/connection.py", line 846, in cassandra.connection.Connection.factory
  File "/home/airflow/.local/lib/python3.8/site-packages/cassandra/io/libevreactor.py", line 266, in __init__
    self._connect_socket()
  File "cassandra/connection.py", line 951, in cassandra.connection.Connection._connect_socket
ConnectionRefusedError: [Errno 111] Tried connecting to [('172.21.0.4', 9042)]. Last error: Connection refused
[2024-04-08T15:12:31.911+0000] {thread.py:57} WARNING - [control connection] Error connecting to 172.21.0.4:9042:
Traceback (most recent call last):
  File "cassandra/cluster.py", line 3577, in cassandra.cluster.ControlConnection._reconnect_internal
  File "cassandra/cluster.py", line 3599, in cassandra.cluster.ControlConnection._try_connect
  File "cassandra/cluster.py", line 1670, in cassandra.cluster.Cluster.connection_factory
  File "cassandra/connection.py", line 846, in cassandra.connection.Connection.factory
  File "/home/airflow/.local/lib/python3.8/site-packages/cassandra/io/libevreactor.py", line 266, in __init__
    self._connect_socket()
  File "cassandra/connection.py", line 951, in cassandra.connection.Connection._connect_socket
ConnectionRefusedError: [Errno 111] Tried connecting to [('172.21.0.4', 9042)]. Last error: Connection refused
[2024-04-08T15:12:32.013+0000] {thread.py:57} WARNING - [control connection] Error connecting to 172.21.0.4:9042:
Traceback (most recent call last):
  File "cassandra/cluster.py", line 3577, in cassandra.cluster.ControlConnection._reconnect_internal
  File "cassandra/cluster.py", line 3599, in cassandra.cluster.ControlConnection._try_connect
  File "cassandra/cluster.py", line 1670, in cassandra.cluster.Cluster.connection_factory
  File "cassandra/connection.py", line 846, in cassandra.connection.Connection.factory
  File "/home/airflow/.local/lib/python3.8/site-packages/cassandra/io/libevreactor.py", line 266, in __init__
    self._connect_socket()
  File "cassandra/connection.py", line 951, in cassandra.connection.Connection._connect_socket
ConnectionRefusedError: [Errno 111] Tried connecting to [('172.21.0.4', 9042)]. Last error: Connection refused
[2024-04-08T15:12:35.311+0000] {thread.py:57} WARNING - [control connection] Error connecting to 172.21.0.4:9042:
Traceback (most recent call last):
  File "cassandra/cluster.py", line 3577, in cassandra.cluster.ControlConnection._reconnect_internal
  File "cassandra/cluster.py", line 3599, in cassandra.cluster.ControlConnection._try_connect
  File "cassandra/cluster.py", line 1670, in cassandra.cluster.Cluster.connection_factory
  File "cassandra/connection.py", line 846, in cassandra.connection.Connection.factory
  File "/home/airflow/.local/lib/python3.8/site-packages/cassandra/io/libevreactor.py", line 266, in __init__
    self._connect_socket()
  File "cassandra/connection.py", line 951, in cassandra.connection.Connection._connect_socket
ConnectionRefusedError: [Errno 111] Tried connecting to [('172.21.0.4', 9042)]. Last error: Connection refused
[2024-04-08T15:12:35.937+0000] {thread.py:57} WARNING - [control connection] Error connecting to 172.21.0.4:9042:
Traceback (most recent call last):
  File "cassandra/cluster.py", line 3577, in cassandra.cluster.ControlConnection._reconnect_internal
  File "cassandra/cluster.py", line 3599, in cassandra.cluster.ControlConnection._try_connect
  File "cassandra/cluster.py", line 1670, in cassandra.cluster.Cluster.connection_factory
  File "cassandra/connection.py", line 846, in cassandra.connection.Connection.factory
  File "/home/airflow/.local/lib/python3.8/site-packages/cassandra/io/libevreactor.py", line 266, in __init__
    self._connect_socket()
  File "cassandra/connection.py", line 951, in cassandra.connection.Connection._connect_socket
ConnectionRefusedError: [Errno 111] Tried connecting to [('172.21.0.4', 9042)]. Last error: Connection refused
[2024-04-08T15:12:35.940+0000] {thread.py:57} WARNING - [control connection] Error connecting to 172.21.0.4:9042:
Traceback (most recent call last):
  File "cassandra/cluster.py", line 3577, in cassandra.cluster.ControlConnection._reconnect_internal
  File "cassandra/cluster.py", line 3599, in cassandra.cluster.ControlConnection._try_connect
  File "cassandra/cluster.py", line 1670, in cassandra.cluster.Cluster.connection_factory
  File "cassandra/connection.py", line 846, in cassandra.connection.Connection.factory
  File "/home/airflow/.local/lib/python3.8/site-packages/cassandra/io/libevreactor.py", line 266, in __init__
    self._connect_socket()
  File "cassandra/connection.py", line 951, in cassandra.connection.Connection._connect_socket
ConnectionRefusedError: [Errno 111] Tried connecting to [('172.21.0.4', 9042)]. Last error: Connection refused
[2024-04-08T15:12:36.016+0000] {thread.py:57} WARNING - [control connection] Error connecting to 172.21.0.4:9042:
Traceback (most recent call last):
  File "cassandra/cluster.py", line 3577, in cassandra.cluster.ControlConnection._reconnect_internal
  File "cassandra/cluster.py", line 3599, in cassandra.cluster.ControlConnection._try_connect
  File "cassandra/cluster.py", line 1670, in cassandra.cluster.Cluster.connection_factory
  File "cassandra/connection.py", line 846, in cassandra.connection.Connection.factory
  File "/home/airflow/.local/lib/python3.8/site-packages/cassandra/io/libevreactor.py", line 266, in __init__
    self._connect_socket()
  File "cassandra/connection.py", line 951, in cassandra.connection.Connection._connect_socket
ConnectionRefusedError: [Errno 111] Tried connecting to [('172.21.0.4', 9042)]. Last error: Connection refused
[2024-04-08T15:12:36.324+0000] {thread.py:57} WARNING - [control connection] Error connecting to 172.21.0.4:9042:
Traceback (most recent call last):
  File "cassandra/cluster.py", line 3577, in cassandra.cluster.ControlConnection._reconnect_internal
  File "cassandra/cluster.py", line 3599, in cassandra.cluster.ControlConnection._try_connect
  File "cassandra/cluster.py", line 1670, in cassandra.cluster.Cluster.connection_factory
  File "cassandra/connection.py", line 846, in cassandra.connection.Connection.factory
  File "/home/airflow/.local/lib/python3.8/site-packages/cassandra/io/libevreactor.py", line 266, in __init__
    self._connect_socket()
  File "cassandra/connection.py", line 951, in cassandra.connection.Connection._connect_socket
ConnectionRefusedError: [Errno 111] Tried connecting to [('172.21.0.4', 9042)]. Last error: Connection refused
[2024-04-08T15:12:43.081+0000] {thread.py:57} WARNING - [control connection] Error connecting to 172.21.0.4:9042:
Traceback (most recent call last):
  File "cassandra/cluster.py", line 3577, in cassandra.cluster.ControlConnection._reconnect_internal
  File "cassandra/cluster.py", line 3599, in cassandra.cluster.ControlConnection._try_connect
  File "cassandra/cluster.py", line 1670, in cassandra.cluster.Cluster.connection_factory
  File "cassandra/connection.py", line 846, in cassandra.connection.Connection.factory
  File "/home/airflow/.local/lib/python3.8/site-packages/cassandra/io/libevreactor.py", line 266, in __init__
    self._connect_socket()
  File "cassandra/connection.py", line 951, in cassandra.connection.Connection._connect_socket
ConnectionRefusedError: [Errno 111] Tried connecting to [('172.21.0.4', 9042)]. Last error: Connection refused
[2024-04-08T15:12:43.157+0000] {thread.py:57} WARNING - [control connection] Error connecting to 172.21.0.4:9042:
Traceback (most recent call last):
  File "cassandra/cluster.py", line 3577, in cassandra.cluster.ControlConnection._reconnect_internal
  File "cassandra/cluster.py", line 3599, in cassandra.cluster.ControlConnection._try_connect
  File "cassandra/cluster.py", line 1670, in cassandra.cluster.Cluster.connection_factory
  File "cassandra/connection.py", line 846, in cassandra.connection.Connection.factory
  File "/home/airflow/.local/lib/python3.8/site-packages/cassandra/io/libevreactor.py", line 266, in __init__
    self._connect_socket()
  File "cassandra/connection.py", line 951, in cassandra.connection.Connection._connect_socket
ConnectionRefusedError: [Errno 111] Tried connecting to [('172.21.0.4', 9042)]. Last error: Connection refused
[2024-04-08T15:12:43.667+0000] {thread.py:57} WARNING - [control connection] Error connecting to 172.21.0.4:9042:
Traceback (most recent call last):
  File "cassandra/cluster.py", line 3577, in cassandra.cluster.ControlConnection._reconnect_internal
  File "cassandra/cluster.py", line 3599, in cassandra.cluster.ControlConnection._try_connect
  File "cassandra/cluster.py", line 1670, in cassandra.cluster.Cluster.connection_factory
  File "cassandra/connection.py", line 846, in cassandra.connection.Connection.factory
  File "/home/airflow/.local/lib/python3.8/site-packages/cassandra/io/libevreactor.py", line 266, in __init__
    self._connect_socket()
  File "cassandra/connection.py", line 951, in cassandra.connection.Connection._connect_socket
ConnectionRefusedError: [Errno 111] Tried connecting to [('172.21.0.4', 9042)]. Last error: Connection refused
[2024-04-08T15:12:43.854+0000] {thread.py:57} WARNING - [control connection] Error connecting to 172.21.0.4:9042:
Traceback (most recent call last):
  File "cassandra/cluster.py", line 3577, in cassandra.cluster.ControlConnection._reconnect_internal
  File "cassandra/cluster.py", line 3599, in cassandra.cluster.ControlConnection._try_connect
  File "cassandra/cluster.py", line 1670, in cassandra.cluster.Cluster.connection_factory
  File "cassandra/connection.py", line 846, in cassandra.connection.Connection.factory
  File "/home/airflow/.local/lib/python3.8/site-packages/cassandra/io/libevreactor.py", line 266, in __init__
    self._connect_socket()
  File "cassandra/connection.py", line 951, in cassandra.connection.Connection._connect_socket
ConnectionRefusedError: [Errno 111] Tried connecting to [('172.21.0.4', 9042)]. Last error: Connection refused
[2024-04-08T15:12:44.690+0000] {thread.py:57} WARNING - [control connection] Error connecting to 172.21.0.4:9042:
Traceback (most recent call last):
  File "cassandra/cluster.py", line 3577, in cassandra.cluster.ControlConnection._reconnect_internal
  File "cassandra/cluster.py", line 3599, in cassandra.cluster.ControlConnection._try_connect
  File "cassandra/cluster.py", line 1670, in cassandra.cluster.Cluster.connection_factory
  File "cassandra/connection.py", line 846, in cassandra.connection.Connection.factory
  File "/home/airflow/.local/lib/python3.8/site-packages/cassandra/io/libevreactor.py", line 266, in __init__
    self._connect_socket()
  File "cassandra/connection.py", line 951, in cassandra.connection.Connection._connect_socket
ConnectionRefusedError: [Errno 111] Tried connecting to [('172.21.0.4', 9042)]. Last error: Connection refused
[2024-04-08T15:13:31.014+0000] {record.py:71} INFO - Sensor check existence of record: ['user_id', 'age', 'email', 'name']
[2024-04-08T15:13:31.041+0000] {base.py:83} INFO - Using connection ID 'cassandra_conn' for task execution.
[2024-04-08T15:13:31.086+0000] {cassandra.py:128} WARNING - Downgrading core protocol version from 66 to 65 for 172.21.0.4:9042. To avoid this, it is best practice to explicitly set Cluster(protocol_version) to the version supported by your cluster. http://datastax.github.io/python-driver/api/cassandra/cluster.html#cassandra.cluster.Cluster.protocol_version
[2024-04-08T15:13:31.093+0000] {cassandra.py:128} WARNING - Downgrading core protocol version from 65 to 5 for 172.21.0.4:9042. To avoid this, it is best practice to explicitly set Cluster(protocol_version) to the version supported by your cluster. http://datastax.github.io/python-driver/api/cassandra/cluster.html#cassandra.cluster.Cluster.protocol_version
[2024-04-08T15:14:31.359+0000] {record.py:71} INFO - Sensor check existence of record: ['user_id', 'age', 'email', 'name']
[2024-04-08T15:14:31.696+0000] {base.py:83} INFO - Using connection ID 'cassandra_conn' for task execution.
[2024-04-08T15:14:31.804+0000] {cassandra.py:128} WARNING - Downgrading core protocol version from 66 to 65 for 172.21.0.4:9042. To avoid this, it is best practice to explicitly set Cluster(protocol_version) to the version supported by your cluster. http://datastax.github.io/python-driver/api/cassandra/cluster.html#cassandra.cluster.Cluster.protocol_version
[2024-04-08T15:14:31.830+0000] {cassandra.py:128} WARNING - Downgrading core protocol version from 65 to 5 for 172.21.0.4:9042. To avoid this, it is best practice to explicitly set Cluster(protocol_version) to the version supported by your cluster. http://datastax.github.io/python-driver/api/cassandra/cluster.html#cassandra.cluster.Cluster.protocol_version
[2024-04-08T15:15:31.741+0000] {job.py:221} ERROR - Job heartbeat failed with error. Scheduler is in unhealthy state
[2024-04-08T15:15:33.651+0000] {record.py:71} INFO - Sensor check existence of record: ['user_id', 'age', 'email', 'name']
[2024-04-08T15:15:35.716+0000] {base.py:83} INFO - Using connection ID 'cassandra_conn' for task execution.
[2024-04-08T15:15:35.980+0000] {cassandra.py:128} WARNING - Downgrading core protocol version from 66 to 65 for 172.21.0.4:9042. To avoid this, it is best practice to explicitly set Cluster(protocol_version) to the version supported by your cluster. http://datastax.github.io/python-driver/api/cassandra/cluster.html#cassandra.cluster.Cluster.protocol_version
[2024-04-08T15:15:36.002+0000] {cassandra.py:128} WARNING - Downgrading core protocol version from 65 to 5 for 172.21.0.4:9042. To avoid this, it is best practice to explicitly set Cluster(protocol_version) to the version supported by your cluster. http://datastax.github.io/python-driver/api/cassandra/cluster.html#cassandra.cluster.Cluster.protocol_version
[2024-04-08T15:15:36.572+0000] {taskinstance.py:2731} ERROR - Task failed with exception
Traceback (most recent call last):
  File "/home/airflow/.local/lib/python3.8/site-packages/airflow/models/taskinstance.py", line 444, in _execute_task
    result = _execute_callable(context=context, **execute_callable_kwargs)
  File "/home/airflow/.local/lib/python3.8/site-packages/airflow/models/taskinstance.py", line 414, in _execute_callable
    return execute_callable(context=context, **execute_callable_kwargs)
  File "/home/airflow/.local/lib/python3.8/site-packages/airflow/sensors/base.py", line 282, in execute
    raise AirflowSensorTimeout(message)
airflow.exceptions.AirflowSensorTimeout: Sensor has timed out; run duration of 643.0210868040012 seconds exceeds the specified timeout of 600.0.
[2024-04-08T15:15:36.719+0000] {taskinstance.py:1149} INFO - Immediate failure requested. Marking task as FAILED. dag_id=cassandra_sensor_dag, task_id=cassandra_sensor_record, execution_date=20240408T010500, start_date=20240408T150450, end_date=20240408T151536
[2024-04-08T15:15:37.223+0000] {standard_task_runner.py:107} ERROR - Failed to execute job 135 for task cassandra_sensor_record (Sensor has timed out; run duration of 643.0210868040012 seconds exceeds the specified timeout of 600.0.; 1630)
[2024-04-08T15:15:37.966+0000] {local_task_job_runner.py:234} INFO - Task exited with return code 1
[2024-04-08T15:15:38.952+0000] {taskinstance.py:3312} INFO - 0 downstream tasks scheduled from follow-on schedule check
