[2024-04-08T15:17:09.187+0000] {taskinstance.py:1979} INFO - Dependencies all met for dep_context=non-requeueable deps ti=<TaskInstance: cassandra_sensor_dag.cassandra_sensor_record scheduled__2024-04-08T00:05:00+00:00 [queued]>
[2024-04-08T15:17:09.324+0000] {taskinstance.py:1979} INFO - Dependencies all met for dep_context=requeueable deps ti=<TaskInstance: cassandra_sensor_dag.cassandra_sensor_record scheduled__2024-04-08T00:05:00+00:00 [queued]>
[2024-04-08T15:17:09.354+0000] {taskinstance.py:2193} INFO - Starting attempt 2 of 2
[2024-04-08T15:17:10.514+0000] {taskinstance.py:2217} INFO - Executing <Task(CassandraRecordSensor): cassandra_sensor_record> on 2024-04-08 00:05:00+00:00
[2024-04-08T15:17:10.759+0000] {standard_task_runner.py:60} INFO - Started process 2433 to run task
[2024-04-08T15:17:10.817+0000] {standard_task_runner.py:87} INFO - Running: ['***', 'tasks', 'run', 'cassandra_sensor_dag', 'cassandra_sensor_record', 'scheduled__2024-04-08T00:05:00+00:00', '--job-id', '165', '--raw', '--subdir', 'DAGS_FOLDER/test.py', '--cfg-path', '/tmp/tmpxz7y35xf']
[2024-04-08T15:17:10.899+0000] {standard_task_runner.py:88} INFO - Job 165: Subtask cassandra_sensor_record
[2024-04-08T15:17:12.004+0000] {task_command.py:423} INFO - Running <TaskInstance: cassandra_sensor_dag.cassandra_sensor_record scheduled__2024-04-08T00:05:00+00:00 [running]> on host c2d2cc8ff432
[2024-04-08T15:17:12.887+0000] {taskinstance.py:2513} INFO - Exporting env vars: AIRFLOW_CTX_DAG_OWNER='***' AIRFLOW_CTX_DAG_ID='cassandra_sensor_dag' AIRFLOW_CTX_TASK_ID='cassandra_sensor_record' AIRFLOW_CTX_EXECUTION_DATE='2024-04-08T00:05:00+00:00' AIRFLOW_CTX_TRY_NUMBER='2' AIRFLOW_CTX_DAG_RUN_ID='scheduled__2024-04-08T00:05:00+00:00'
[2024-04-08T15:17:12.932+0000] {record.py:71} INFO - Sensor check existence of record: ['user_id']
[2024-04-08T15:17:13.039+0000] {base.py:83} INFO - Using connection ID 'cassandra_conn' for task execution.
[2024-04-08T15:17:13.055+0000] {warnings.py:109} WARNING - /home/***/.local/lib/python3.8/site-packages/***/providers/apache/cassandra/hooks/cassandra.py:120: DeprecationWarning: Legacy execution parameters will be removed in 4.0. Consider using execution profiles.
  self.cluster = Cluster(**conn_config)

[2024-04-08T15:17:13.081+0000] {cassandra.py:128} WARNING - Downgrading core protocol version from 66 to 65 for 172.21.0.4:9042. To avoid this, it is best practice to explicitly set Cluster(protocol_version) to the version supported by your cluster. http://datastax.github.io/python-driver/api/cassandra/cluster.html#cassandra.cluster.Cluster.protocol_version
[2024-04-08T15:17:13.095+0000] {cassandra.py:128} WARNING - Downgrading core protocol version from 65 to 5 for 172.21.0.4:9042. To avoid this, it is best practice to explicitly set Cluster(protocol_version) to the version supported by your cluster. http://datastax.github.io/python-driver/api/cassandra/cluster.html#cassandra.cluster.Cluster.protocol_version
[2024-04-08T15:18:14.144+0000] {record.py:71} INFO - Sensor check existence of record: ['user_id']
[2024-04-08T15:20:38.392+0000] {threading.py:932} WARNING - Heartbeat failed for connection (140560711306064) to 172.21.0.4:9042
[2024-04-08T15:20:38.439+0000] {thread.py:57} WARNING - [control connection] Error connecting to 172.21.0.4:9042:
Traceback (most recent call last):
  File "cassandra/cluster.py", line 3577, in cassandra.cluster.ControlConnection._reconnect_internal
  File "cassandra/cluster.py", line 3599, in cassandra.cluster.ControlConnection._try_connect
  File "cassandra/cluster.py", line 1670, in cassandra.cluster.Cluster.connection_factory
  File "cassandra/connection.py", line 846, in cassandra.connection.Connection.factory
  File "/home/airflow/.local/lib/python3.8/site-packages/cassandra/io/libevreactor.py", line 266, in __init__
    self._connect_socket()
  File "cassandra/connection.py", line 951, in cassandra.connection.Connection._connect_socket
ConnectionRefusedError: [Errno 111] Tried connecting to [('172.21.0.4', 9042)]. Last error: Connection refused
[2024-04-08T15:17:37.168+0000] {job.py:213} ERROR - Job heartbeat got an exception
Traceback (most recent call last):
  File "/home/airflow/.local/lib/python3.8/site-packages/sqlalchemy/engine/base.py", line 3371, in _wrap_pool_connect
    return fn()
  File "/home/airflow/.local/lib/python3.8/site-packages/sqlalchemy/pool/base.py", line 327, in connect
    return _ConnectionFairy._checkout(self)
  File "/home/airflow/.local/lib/python3.8/site-packages/sqlalchemy/pool/base.py", line 894, in _checkout
    fairy = _ConnectionRecord.checkout(pool)
  File "/home/airflow/.local/lib/python3.8/site-packages/sqlalchemy/pool/base.py", line 493, in checkout
    rec = pool._do_get()
  File "/home/airflow/.local/lib/python3.8/site-packages/sqlalchemy/pool/impl.py", line 256, in _do_get
    return self._create_connection()
  File "/home/airflow/.local/lib/python3.8/site-packages/sqlalchemy/pool/base.py", line 273, in _create_connection
    return _ConnectionRecord(self)
  File "/home/airflow/.local/lib/python3.8/site-packages/sqlalchemy/pool/base.py", line 388, in __init__
    self.__connect()
  File "/home/airflow/.local/lib/python3.8/site-packages/sqlalchemy/pool/base.py", line 691, in __connect
    pool.logger.debug("Error on connect(): %s", e)
  File "/home/airflow/.local/lib/python3.8/site-packages/sqlalchemy/util/langhelpers.py", line 70, in __exit__
    compat.raise_(
  File "/home/airflow/.local/lib/python3.8/site-packages/sqlalchemy/util/compat.py", line 211, in raise_
    raise exception
  File "/home/airflow/.local/lib/python3.8/site-packages/sqlalchemy/pool/base.py", line 686, in __connect
    self.dbapi_connection = connection = pool._invoke_creator(self)
  File "/home/airflow/.local/lib/python3.8/site-packages/sqlalchemy/engine/create.py", line 574, in connect
    return dialect.connect(*cargs, **cparams)
  File "/home/airflow/.local/lib/python3.8/site-packages/sqlalchemy/engine/default.py", line 598, in connect
    return self.dbapi.connect(*cargs, **cparams)
  File "/home/airflow/.local/lib/python3.8/site-packages/psycopg2/__init__.py", line 122, in connect
    conn = _connect(dsn, connection_factory=connection_factory, **kwasync)
psycopg2.OperationalError: could not translate host name "postgres" to address: Temporary failure in name resolution


The above exception was the direct cause of the following exception:

Traceback (most recent call last):
  File "/home/airflow/.local/lib/python3.8/site-packages/airflow/jobs/job.py", line 187, in heartbeat
    self._merge_from(Job._fetch_from_db(self, session))
  File "/home/airflow/.local/lib/python3.8/site-packages/airflow/api_internal/internal_api_call.py", line 114, in wrapper
    return func(*args, **kwargs)
  File "/home/airflow/.local/lib/python3.8/site-packages/airflow/utils/session.py", line 76, in wrapper
    return func(*args, **kwargs)
  File "/home/airflow/.local/lib/python3.8/site-packages/airflow/jobs/job.py", line 310, in _fetch_from_db
    session.merge(job)
  File "/home/airflow/.local/lib/python3.8/site-packages/sqlalchemy/orm/session.py", line 3056, in merge
    return self._merge(
  File "/home/airflow/.local/lib/python3.8/site-packages/sqlalchemy/orm/session.py", line 3136, in _merge
    merged = self.get(
  File "/home/airflow/.local/lib/python3.8/site-packages/sqlalchemy/orm/session.py", line 2853, in get
    return self._get_impl(
  File "/home/airflow/.local/lib/python3.8/site-packages/sqlalchemy/orm/session.py", line 2975, in _get_impl
    return db_load_fn(
  File "/home/airflow/.local/lib/python3.8/site-packages/sqlalchemy/orm/loading.py", line 530, in load_on_pk_identity
    session.execute(
  File "/home/airflow/.local/lib/python3.8/site-packages/sqlalchemy/orm/session.py", line 1716, in execute
    conn = self._connection_for_bind(bind)
  File "/home/airflow/.local/lib/python3.8/site-packages/sqlalchemy/orm/session.py", line 1555, in _connection_for_bind
    return self._transaction._connection_for_bind(
  File "/home/airflow/.local/lib/python3.8/site-packages/sqlalchemy/orm/session.py", line 750, in _connection_for_bind
    conn = bind.connect()
  File "/home/airflow/.local/lib/python3.8/site-packages/sqlalchemy/future/engine.py", line 412, in connect
    return super(Engine, self).connect()
  File "/home/airflow/.local/lib/python3.8/site-packages/sqlalchemy/engine/base.py", line 3325, in connect
    return self._connection_cls(self, close_with_result=close_with_result)
  File "/home/airflow/.local/lib/python3.8/site-packages/sqlalchemy/engine/base.py", line 96, in __init__
    else engine.raw_connection()
  File "/home/airflow/.local/lib/python3.8/site-packages/sqlalchemy/engine/base.py", line 3404, in raw_connection
    return self._wrap_pool_connect(self.pool.connect, _connection)
  File "/home/airflow/.local/lib/python3.8/site-packages/sqlalchemy/engine/base.py", line 3374, in _wrap_pool_connect
    Connection._handle_dbapi_exception_noconnection(
  File "/home/airflow/.local/lib/python3.8/site-packages/sqlalchemy/engine/base.py", line 2208, in _handle_dbapi_exception_noconnection
    util.raise_(
  File "/home/airflow/.local/lib/python3.8/site-packages/sqlalchemy/util/compat.py", line 211, in raise_
    raise exception
  File "/home/airflow/.local/lib/python3.8/site-packages/sqlalchemy/engine/base.py", line 3371, in _wrap_pool_connect
    return fn()
  File "/home/airflow/.local/lib/python3.8/site-packages/sqlalchemy/pool/base.py", line 327, in connect
    return _ConnectionFairy._checkout(self)
  File "/home/airflow/.local/lib/python3.8/site-packages/sqlalchemy/pool/base.py", line 894, in _checkout
    fairy = _ConnectionRecord.checkout(pool)
  File "/home/airflow/.local/lib/python3.8/site-packages/sqlalchemy/pool/base.py", line 493, in checkout
    rec = pool._do_get()
  File "/home/airflow/.local/lib/python3.8/site-packages/sqlalchemy/pool/impl.py", line 256, in _do_get
    return self._create_connection()
  File "/home/airflow/.local/lib/python3.8/site-packages/sqlalchemy/pool/base.py", line 273, in _create_connection
    return _ConnectionRecord(self)
  File "/home/airflow/.local/lib/python3.8/site-packages/sqlalchemy/pool/base.py", line 388, in __init__
    self.__connect()
  File "/home/airflow/.local/lib/python3.8/site-packages/sqlalchemy/pool/base.py", line 691, in __connect
    pool.logger.debug("Error on connect(): %s", e)
  File "/home/airflow/.local/lib/python3.8/site-packages/sqlalchemy/util/langhelpers.py", line 70, in __exit__
    compat.raise_(
  File "/home/airflow/.local/lib/python3.8/site-packages/sqlalchemy/util/compat.py", line 211, in raise_
    raise exception
  File "/home/airflow/.local/lib/python3.8/site-packages/sqlalchemy/pool/base.py", line 686, in __connect
    self.dbapi_connection = connection = pool._invoke_creator(self)
  File "/home/airflow/.local/lib/python3.8/site-packages/sqlalchemy/engine/create.py", line 574, in connect
    return dialect.connect(*cargs, **cparams)
  File "/home/airflow/.local/lib/python3.8/site-packages/sqlalchemy/engine/default.py", line 598, in connect
    return self.dbapi.connect(*cargs, **cparams)
  File "/home/airflow/.local/lib/python3.8/site-packages/psycopg2/__init__.py", line 122, in connect
    conn = _connect(dsn, connection_factory=connection_factory, **kwasync)
sqlalchemy.exc.OperationalError: (psycopg2.OperationalError) could not translate host name "postgres" to address: Temporary failure in name resolution

(Background on this error at: https://sqlalche.me/e/14/e3q8)
[2024-04-08T15:20:38.527+0000] {job.py:221} ERROR - Job heartbeat failed with error. Scheduler is in unhealthy state
[2024-04-08T15:20:39.664+0000] {thread.py:57} WARNING - [control connection] Error connecting to 172.21.0.4:9042:
Traceback (most recent call last):
  File "cassandra/cluster.py", line 3577, in cassandra.cluster.ControlConnection._reconnect_internal
  File "cassandra/cluster.py", line 3599, in cassandra.cluster.ControlConnection._try_connect
  File "cassandra/cluster.py", line 1670, in cassandra.cluster.Cluster.connection_factory
  File "cassandra/connection.py", line 846, in cassandra.connection.Connection.factory
  File "/home/airflow/.local/lib/python3.8/site-packages/cassandra/io/libevreactor.py", line 266, in __init__
    self._connect_socket()
  File "cassandra/connection.py", line 951, in cassandra.connection.Connection._connect_socket
ConnectionRefusedError: [Errno 111] Tried connecting to [('172.21.0.4', 9042)]. Last error: Connection refused
[2024-04-08T15:20:39.813+0000] {base.py:83} INFO - Using connection ID 'cassandra_conn' for task execution.
[2024-04-08T15:20:39.835+0000] {cassandra.py:128} WARNING - [control connection] Error connecting to 172.21.0.4:9042:
Traceback (most recent call last):
  File "cassandra/cluster.py", line 3577, in cassandra.cluster.ControlConnection._reconnect_internal
  File "cassandra/cluster.py", line 3599, in cassandra.cluster.ControlConnection._try_connect
  File "cassandra/cluster.py", line 1670, in cassandra.cluster.Cluster.connection_factory
  File "cassandra/connection.py", line 846, in cassandra.connection.Connection.factory
  File "/home/airflow/.local/lib/python3.8/site-packages/cassandra/io/libevreactor.py", line 266, in __init__
    self._connect_socket()
  File "cassandra/connection.py", line 951, in cassandra.connection.Connection._connect_socket
ConnectionRefusedError: [Errno 111] Tried connecting to [('172.21.0.4', 9042)]. Last error: Connection refused
[2024-04-08T15:20:39.844+0000] {cassandra.py:128} ERROR - Control connection failed to connect, shutting down Cluster:
Traceback (most recent call last):
  File "cassandra/cluster.py", line 1740, in cassandra.cluster.Cluster.connect
  File "cassandra/cluster.py", line 3543, in cassandra.cluster.ControlConnection.connect
  File "cassandra/cluster.py", line 3588, in cassandra.cluster.ControlConnection._reconnect_internal
cassandra.cluster.NoHostAvailable: ('Unable to connect to any servers', {'172.21.0.4:9042': ConnectionRefusedError(111, "Tried connecting to [('172.21.0.4', 9042)]. Last error: Connection refused")})
[2024-04-08T15:20:46.619+0000] {thread.py:57} WARNING - [control connection] Error connecting to 172.21.0.4:9042:
Traceback (most recent call last):
  File "cassandra/cluster.py", line 3577, in cassandra.cluster.ControlConnection._reconnect_internal
  File "cassandra/cluster.py", line 3599, in cassandra.cluster.ControlConnection._try_connect
  File "cassandra/cluster.py", line 1670, in cassandra.cluster.Cluster.connection_factory
  File "cassandra/connection.py", line 846, in cassandra.connection.Connection.factory
  File "/home/airflow/.local/lib/python3.8/site-packages/cassandra/io/libevreactor.py", line 266, in __init__
    self._connect_socket()
  File "cassandra/connection.py", line 951, in cassandra.connection.Connection._connect_socket
OSError: [Errno None] Tried connecting to [('172.21.0.4', 9042)]. Last error: timed out
[2024-04-08T15:20:53.345+0000] {thread.py:57} WARNING - [control connection] Error connecting to 172.21.0.4:9042:
Traceback (most recent call last):
  File "cassandra/cluster.py", line 3577, in cassandra.cluster.ControlConnection._reconnect_internal
  File "cassandra/cluster.py", line 3599, in cassandra.cluster.ControlConnection._try_connect
  File "cassandra/cluster.py", line 1670, in cassandra.cluster.Cluster.connection_factory
  File "cassandra/connection.py", line 846, in cassandra.connection.Connection.factory
  File "/home/airflow/.local/lib/python3.8/site-packages/cassandra/io/libevreactor.py", line 266, in __init__
    self._connect_socket()
  File "cassandra/connection.py", line 951, in cassandra.connection.Connection._connect_socket
OSError: [Errno 113] Tried connecting to [('172.21.0.4', 9042)]. Last error: No route to host
[2024-04-08T15:21:01.655+0000] {thread.py:57} WARNING - [control connection] Error connecting to 172.21.0.4:9042:
Traceback (most recent call last):
  File "cassandra/cluster.py", line 3577, in cassandra.cluster.ControlConnection._reconnect_internal
  File "cassandra/cluster.py", line 3599, in cassandra.cluster.ControlConnection._try_connect
  File "cassandra/cluster.py", line 1670, in cassandra.cluster.Cluster.connection_factory
  File "cassandra/connection.py", line 846, in cassandra.connection.Connection.factory
  File "/home/airflow/.local/lib/python3.8/site-packages/cassandra/io/libevreactor.py", line 266, in __init__
    self._connect_socket()
  File "cassandra/connection.py", line 951, in cassandra.connection.Connection._connect_socket
ConnectionRefusedError: [Errno 111] Tried connecting to [('172.21.0.4', 9042)]. Last error: Connection refused
[2024-04-08T15:21:08.373+0000] {thread.py:57} WARNING - [control connection] Error connecting to 172.21.0.4:9042:
Traceback (most recent call last):
  File "cassandra/cluster.py", line 3577, in cassandra.cluster.ControlConnection._reconnect_internal
  File "cassandra/cluster.py", line 3599, in cassandra.cluster.ControlConnection._try_connect
  File "cassandra/cluster.py", line 1670, in cassandra.cluster.Cluster.connection_factory
  File "cassandra/connection.py", line 846, in cassandra.connection.Connection.factory
  File "/home/airflow/.local/lib/python3.8/site-packages/cassandra/io/libevreactor.py", line 266, in __init__
    self._connect_socket()
  File "cassandra/connection.py", line 951, in cassandra.connection.Connection._connect_socket
ConnectionRefusedError: [Errno 111] Tried connecting to [('172.21.0.4', 9042)]. Last error: Connection refused
[2024-04-08T15:21:09.503+0000] {thread.py:57} WARNING - [control connection] Error connecting to 172.21.0.4:9042:
Traceback (most recent call last):
  File "cassandra/cluster.py", line 3577, in cassandra.cluster.ControlConnection._reconnect_internal
  File "cassandra/cluster.py", line 3599, in cassandra.cluster.ControlConnection._try_connect
  File "cassandra/cluster.py", line 1670, in cassandra.cluster.Cluster.connection_factory
  File "cassandra/connection.py", line 846, in cassandra.connection.Connection.factory
  File "/home/airflow/.local/lib/python3.8/site-packages/cassandra/io/libevreactor.py", line 266, in __init__
    self._connect_socket()
  File "cassandra/connection.py", line 951, in cassandra.connection.Connection._connect_socket
ConnectionRefusedError: [Errno 111] Tried connecting to [('172.21.0.4', 9042)]. Last error: Connection refused
[2024-04-08T15:21:11.320+0000] {thread.py:57} WARNING - [control connection] Error connecting to 172.21.0.4:9042:
Traceback (most recent call last):
  File "cassandra/cluster.py", line 3577, in cassandra.cluster.ControlConnection._reconnect_internal
  File "cassandra/cluster.py", line 3599, in cassandra.cluster.ControlConnection._try_connect
  File "cassandra/cluster.py", line 1670, in cassandra.cluster.Cluster.connection_factory
  File "cassandra/connection.py", line 846, in cassandra.connection.Connection.factory
  File "/home/airflow/.local/lib/python3.8/site-packages/cassandra/io/libevreactor.py", line 266, in __init__
    self._connect_socket()
  File "cassandra/connection.py", line 951, in cassandra.connection.Connection._connect_socket
ConnectionRefusedError: [Errno 111] Tried connecting to [('172.21.0.4', 9042)]. Last error: Connection refused
[2024-04-08T15:21:14.832+0000] {thread.py:57} WARNING - [control connection] Error connecting to 172.21.0.4:9042:
Traceback (most recent call last):
  File "cassandra/cluster.py", line 3577, in cassandra.cluster.ControlConnection._reconnect_internal
  File "cassandra/cluster.py", line 3599, in cassandra.cluster.ControlConnection._try_connect
  File "cassandra/cluster.py", line 1670, in cassandra.cluster.Cluster.connection_factory
  File "cassandra/connection.py", line 846, in cassandra.connection.Connection.factory
  File "/home/airflow/.local/lib/python3.8/site-packages/cassandra/io/libevreactor.py", line 266, in __init__
    self._connect_socket()
  File "cassandra/connection.py", line 951, in cassandra.connection.Connection._connect_socket
ConnectionRefusedError: [Errno 111] Tried connecting to [('172.21.0.4', 9042)]. Last error: Connection refused
[2024-04-08T15:21:22.457+0000] {thread.py:57} WARNING - [control connection] Error connecting to 172.21.0.4:9042:
Traceback (most recent call last):
  File "cassandra/cluster.py", line 3577, in cassandra.cluster.ControlConnection._reconnect_internal
  File "cassandra/cluster.py", line 3599, in cassandra.cluster.ControlConnection._try_connect
  File "cassandra/cluster.py", line 1670, in cassandra.cluster.Cluster.connection_factory
  File "cassandra/connection.py", line 846, in cassandra.connection.Connection.factory
  File "/home/airflow/.local/lib/python3.8/site-packages/cassandra/io/libevreactor.py", line 266, in __init__
    self._connect_socket()
  File "cassandra/connection.py", line 951, in cassandra.connection.Connection._connect_socket
ConnectionRefusedError: [Errno 111] Tried connecting to [('172.21.0.4', 9042)]. Last error: Connection refused
[2024-04-08T15:21:39.931+0000] {record.py:71} INFO - Sensor check existence of record: ['user_id']
[2024-04-08T15:21:39.954+0000] {base.py:83} INFO - Using connection ID 'cassandra_conn' for task execution.
[2024-04-08T15:21:39.966+0000] {cassandra.py:128} WARNING - Downgrading core protocol version from 66 to 65 for 172.21.0.4:9042. To avoid this, it is best practice to explicitly set Cluster(protocol_version) to the version supported by your cluster. http://datastax.github.io/python-driver/api/cassandra/cluster.html#cassandra.cluster.Cluster.protocol_version
[2024-04-08T15:21:40.012+0000] {cassandra.py:128} WARNING - Downgrading core protocol version from 65 to 5 for 172.21.0.4:9042. To avoid this, it is best practice to explicitly set Cluster(protocol_version) to the version supported by your cluster. http://datastax.github.io/python-driver/api/cassandra/cluster.html#cassandra.cluster.Cluster.protocol_version
[2024-04-08T15:22:40.322+0000] {record.py:71} INFO - Sensor check existence of record: ['user_id']
[2024-04-08T15:22:40.348+0000] {base.py:83} INFO - Using connection ID 'cassandra_conn' for task execution.
[2024-04-08T15:22:40.375+0000] {cassandra.py:128} WARNING - Downgrading core protocol version from 66 to 65 for 172.21.0.4:9042. To avoid this, it is best practice to explicitly set Cluster(protocol_version) to the version supported by your cluster. http://datastax.github.io/python-driver/api/cassandra/cluster.html#cassandra.cluster.Cluster.protocol_version
[2024-04-08T15:22:40.390+0000] {cassandra.py:128} WARNING - Downgrading core protocol version from 65 to 5 for 172.21.0.4:9042. To avoid this, it is best practice to explicitly set Cluster(protocol_version) to the version supported by your cluster. http://datastax.github.io/python-driver/api/cassandra/cluster.html#cassandra.cluster.Cluster.protocol_version
[2024-04-08T15:23:40.563+0000] {record.py:71} INFO - Sensor check existence of record: ['user_id']
[2024-04-08T15:23:40.573+0000] {base.py:83} INFO - Using connection ID 'cassandra_conn' for task execution.
[2024-04-08T15:23:40.583+0000] {cassandra.py:128} WARNING - Downgrading core protocol version from 66 to 65 for 172.21.0.4:9042. To avoid this, it is best practice to explicitly set Cluster(protocol_version) to the version supported by your cluster. http://datastax.github.io/python-driver/api/cassandra/cluster.html#cassandra.cluster.Cluster.protocol_version
[2024-04-08T15:23:40.587+0000] {cassandra.py:128} WARNING - Downgrading core protocol version from 65 to 5 for 172.21.0.4:9042. To avoid this, it is best practice to explicitly set Cluster(protocol_version) to the version supported by your cluster. http://datastax.github.io/python-driver/api/cassandra/cluster.html#cassandra.cluster.Cluster.protocol_version
[2024-04-08T15:24:40.735+0000] {record.py:71} INFO - Sensor check existence of record: ['user_id']
[2024-04-08T15:24:40.751+0000] {base.py:83} INFO - Using connection ID 'cassandra_conn' for task execution.
[2024-04-08T15:24:40.762+0000] {cassandra.py:128} WARNING - Downgrading core protocol version from 66 to 65 for 172.21.0.4:9042. To avoid this, it is best practice to explicitly set Cluster(protocol_version) to the version supported by your cluster. http://datastax.github.io/python-driver/api/cassandra/cluster.html#cassandra.cluster.Cluster.protocol_version
[2024-04-08T15:24:40.765+0000] {cassandra.py:128} WARNING - Downgrading core protocol version from 65 to 5 for 172.21.0.4:9042. To avoid this, it is best practice to explicitly set Cluster(protocol_version) to the version supported by your cluster. http://datastax.github.io/python-driver/api/cassandra/cluster.html#cassandra.cluster.Cluster.protocol_version
[2024-04-08T15:25:15.741+0000] {thread.py:57} WARNING - Host 172.21.0.4:9042 has been marked down
[2024-04-08T15:25:15.743+0000] {thread.py:57} WARNING - Host 172.21.0.4:9042 has been marked down
[2024-04-08T15:25:15.772+0000] {thread.py:57} WARNING - Host 172.21.0.4:9042 has been marked down
[2024-04-08T15:25:15.773+0000] {thread.py:57} WARNING - Host 172.21.0.4:9042 has been marked down
[2024-04-08T15:25:15.782+0000] {thread.py:57} WARNING - Host 172.21.0.4:9042 has been marked down
[2024-04-08T15:25:16.822+0000] {thread.py:57} WARNING - Error attempting to reconnect to 172.21.0.4:9042, scheduling retry in 2.18 seconds: [Errno 111] Tried connecting to [('172.21.0.4', 9042)]. Last error: Connection refused
[2024-04-08T15:25:16.865+0000] {thread.py:57} WARNING - Error attempting to reconnect to 172.21.0.4:9042, scheduling retry in 1.86 seconds: [Errno 111] Tried connecting to [('172.21.0.4', 9042)]. Last error: Connection refused
[2024-04-08T15:25:16.892+0000] {thread.py:57} WARNING - Error attempting to reconnect to 172.21.0.4:9042, scheduling retry in 1.76 seconds: [Errno 111] Tried connecting to [('172.21.0.4', 9042)]. Last error: Connection refused
[2024-04-08T15:25:17.069+0000] {thread.py:57} WARNING - Error attempting to reconnect to 172.21.0.4:9042, scheduling retry in 1.94 seconds: [Errno 111] Tried connecting to [('172.21.0.4', 9042)]. Last error: Connection refused
[2024-04-08T15:25:17.090+0000] {thread.py:57} WARNING - Error attempting to reconnect to 172.21.0.4:9042, scheduling retry in 2.26 seconds: [Errno 111] Tried connecting to [('172.21.0.4', 9042)]. Last error: Connection refused
[2024-04-08T15:25:18.699+0000] {thread.py:57} WARNING - Error attempting to reconnect to 172.21.0.4:9042, scheduling retry in 4.12 seconds: [Errno 111] Tried connecting to [('172.21.0.4', 9042)]. Last error: Connection refused
[2024-04-08T15:25:18.780+0000] {thread.py:57} WARNING - Error attempting to reconnect to 172.21.0.4:9042, scheduling retry in 3.44 seconds: [Errno 111] Tried connecting to [('172.21.0.4', 9042)]. Last error: Connection refused
[2024-04-08T15:25:19.039+0000] {thread.py:57} WARNING - Error attempting to reconnect to 172.21.0.4:9042, scheduling retry in 4.28 seconds: [Errno 111] Tried connecting to [('172.21.0.4', 9042)]. Last error: Connection refused
[2024-04-08T15:25:19.082+0000] {thread.py:57} WARNING - Error attempting to reconnect to 172.21.0.4:9042, scheduling retry in 3.64 seconds: [Errno 111] Tried connecting to [('172.21.0.4', 9042)]. Last error: Connection refused
[2024-04-08T15:25:19.400+0000] {thread.py:57} WARNING - Error attempting to reconnect to 172.21.0.4:9042, scheduling retry in 4.0 seconds: [Errno 111] Tried connecting to [('172.21.0.4', 9042)]. Last error: Connection refused
